Workbook

Sheet Total Population
D1: County Growth Projections Total Population
A2: Total Population | AM2: Historic Growth Overview | AQ2: Projected Growth Overview
B3: 1980 | C3: 1990 | D3: 2000 | E3: 2010 | F3: 2020 | G3: 2021 | H3: 2025 | M3: 2030 | R3: 2035 | W3: 2040 | AB3: 2045 | AG3: 2050 | AM3: 1980 - 2021 | AQ3: 2021 - 2050
A4: COUNTY | B4: Estimate (1) | C4: Estimate | D4: Estimate | E4: Estimate | F4: Estimate | G4: Estimate | H4: Forecast (2) | I4: Confidence Limit (upper) (3) | J4: Confidence Limit (lower) (3) | K4: Confidence Interval (upper) (4) | L4: Confidence Interval (lower) (4) | M4: Forecast | N4: Confidence Limit (upper) | O4: Confidence Limit (lower) | P4: Confidence Interval (upper) | Q4: Confidence Interval (lower) | R4: Forecast | S4: Confidence Limit (upper) | T4: Confidence Limit (lower) | U4: Confidence Interval (upper) | V4: Confidence Interval (lower) | W4: Forecast | X4: Confidence Limit (upper) | Y4: Confidence Limit (lower) | Z4: Confidence Interval (upper) | AA4: Confidence Interval (lower) | AB4: Forecast | AC4: Confidence Limit (upper) | AD4: Confidence Limit (lower) | AE4: Confidence Interval (upper) | AF4: Confidence Interval (lower) | AG4: Forecast | AH4: Confidence Limit (upper) | AI4: Confidence Limit (lower) | AJ4: Confidence Interval (upper) | AK4: Confidence Interval (lower) | AM4: Growth | AN4: % Growth | AO4: CAGR (5) | AQ4: Growth | AR4: % Growth | AS4: CAGR
A5: Delaware | B5: 53840 | C5: 67482 | D5: 111759 | E5: 175099 | F5: 215062 | G5: 220740 | H5: 247016 | I5: 248441 | J5: 238464 | K5: =I5-$H$5 -> 1425 | L5: =J5-$H5 -> -8552 | M5: 277484 | N5: 287218 | O5: 256467 | P5: =N5-$M5 -> 9734 | Q5: =O5-$M5 -> -21017 | R5: 310863 | S5: 329249 | T5: 271216 | U5: =S5-$R5 -> 18386 | V5: =T5-$R5 -> -39647 | W5: 340917 | X5: 373888 | Y5: 283357 | Z5: =X5-$W5 -> 32971 | AA5: =Y5-$W5 -> -57560 | AB5: 369307 | AC5: 420768 | AD5: 293257 | AE5: =AC5-$AB5 -> 51461 | AF5: =AD5-$AB5 -> -76050 | AG5: 397697 | AH5: 469644 | AI5: 301161 | AJ5: =AH5-$AG5 -> 71947 | AK5: =AI5-$AG5 -> -96536 | AM5: =G5-B5 -> 166900 | AN5: =AM5/B5 -> 3.0999257 | AO5: =(G5/B5)^(1/($G$3-$B$3))-1 -> 0.035012883 | AQ5: =AG5-G5 -> 176957 | AR5: =AQ5/G5 -> 0.80165353 | AS5: =(AG5/G5)^(1/($AG$3-$G$3))-1 -> 0.020507618
A6: Fairfield | B6: 93678 | C6: 103823 | D6: 123485 | E6: 146417 | F6: 159357 | G6: 161064 | H6: 169183 | I6: 171704 | J6: 163990 | K6: =I6-H6 -> 2521 | L6: =J6-$H6 -> -5193 | M6: 178449 | N6: 188541 | O6: 164104 | P6: =N6-$M6 -> 10092 | Q6: =O6-$M6 -> -14345 | R6: 188820 | S6: 208055 | T6: 161542 | U6: =S6-$R6 -> 19235 | V6: =T6-$R6 -> -27278 | W6: 197928 | X6: 229705 | Y6: 156843 | Z6: =X6-$W6 -> 31777 | AA6: =Y6-$W6 -> -41085 | AB6: 206404 | AC6: 253189 | AD6: 150311 | AE6: =AC6-$AB6 -> 46785 | AF6: =AD6-$AB6 -> -56093 | AG6: 214880 | AH6: 278304 | AI6: 142147 | AJ6: =AH6-$AG6 -> 63424 | AK6: =AI6-$AG6 -> -72733 | AM6: =G6-B6 -> 67386 | AN6: =AM6/B6 -> 0.71933645 | AO6: =(G6/B6)^(1/($G$3-$B$3))-1 -> 0.013305755 | AQ6: =AG6-G6 -> 53816 | AR6: =AQ6/G6 -> 0.33412805 | AS6: =(AG6/G6)^(1/($AG$3-$G$3))-1 -> 0.0099901904
A7: Fayette | B7: 27467 | C7: 27501 | D7: 28495 | E7: 29014 | F7: 28939 | G7: 28906 | H7: 29419 | I7: 29855 | J7: 28912 | K7: =I7-H7 -> 436 | L7: =J7-$H7 -> -507 | M7: 30011 | N7: 31216 | O7: 28691 | P7: =N7-$M7 -> 1205 | Q7: =O7-$M7 -> -1320 | R7: 30634 | S7: 32814 | T7: 28240 | U7: =S7-$R7 -> 2180 | V7: =T7-$R7 -> -2394 | W7: 31220 | X7: 34594 | Y7: 27601 | Z7: =X7-$W7 -> 3374 | AA7: =Y7-$W7 -> -3619 | AB7: 31790 | AC7: 36534 | AD7: 26802 | AE7: =AC7-$AB7 -> 4744 | AF7: =AD7-$AB7 -> -4988 | AG7: 32360 | AH7: 38618 | AI7: 25859 | AJ7: =AH7-$AG7 -> 6258 | AK7: =AI7-$AG7 -> -6501 | AM7: =G7-B7 -> 1439 | AN7: =AM7/B7 -> 0.052390141 | AO7: =(G7/B7)^(1/($G$3-$B$3))-1 -> 0.0012462369 | AQ7: =AG7-G7 -> 3454 | AR7: =AQ7/G7 -> 0.11949076 | AS7: =(AG7/G7)^(1/($AG$3-$G$3))-1 -> 0.0038997881
A8: Franklin | B8: 869126 | C8: 965600 | D8: 1072018 | E8: 1166202 | F8: 1324013 | G8: 1321414 | H8: 1390127 | I8: 1409654 | J8: 1333445 | K8: =I8-H8 -> 19527 | L8: =J8-$H8 -> -56682 | M8: 1447090 | N8: 1506988 | O8: 1327469 | P8: =N8-$M8 -> 59898 | Q8: =O8-$M8 -> -119621 | R8: 1519844 | S8: 1617180 | T8: 1308636 | U8: =S8-$R8 -> 97336 | V8: =T8-$R8 -> -211208 | W8: 1574551 | X8: 1738045 | Y8: 1279131 | Z8: =X8-$W8 -> 163494 | AA8: =Y8-$W8 -> -295420 | AB8: 1620232 | AC8: 1868239 | AD8: 1240296 | AE8: =AC8-$AB8 -> 248007 | AF8: =AD8-$AB8 -> -379936 | AG8: 1665914 | AH8: 2006828 | AI8: 1193066 | AJ8: =AH8-$AG8 -> 340914 | AK8: =AI8-$AG8 -> -472848 | AM8: =G8-B8 -> 452288 | AN8: =AM8/B8 -> 0.52039405 | AO8: =(G8/B8)^(1/($G$3-$B$3))-1 -> 0.010271159 | AQ8: =AG8-G8 -> 344500 | AR8: =AQ8/G8 -> 0.26070558 | AS8: =(AG8/G8)^(1/($AG$3-$G$3))-1 -> 0.0080206686
A9: Hocking | B9: 24304 | C9: 25594 | D9: 28262 | E9: 29478 | F9: 27999 | G9: 28097 | H9: 27965 | I9: 28660 | J9: 27122 | K9: =I9-H9 -> 695 | L9: =J9-$H9 -> -843 | M9: 27762 | N9: 29751 | O9: 25535 | P9: =N9-$M9 -> 1989 | Q9: =O9-$M9 -> -2227 | R9: 27629 | S9: 31239 | T9: 23571 | U9: =S9-$R9 -> 3610 | V9: =T9-$R9 -> -4058 | W9: 27428 | X9: 33041 | Y9: 21295 | Z9: =X9-$W9 -> 5613 | AA9: =Y9-$W9 -> -6133 | AB9: 27190 | AC9: 35114 | AD9: 18747 | AE9: =AC9-$AB9 -> 7924 | AF9: =AD9-$AB9 -> -8443 | AG9: 26953 | AH9: 37429 | AI9: 15958 | AJ9: =AH9-$AG9 -> 10476 | AK9: =AI9-$AG9 -> -10995 | AM9: =G9-B9 -> 3793 | AN9: =AM9/B9 -> 0.15606485 | AO9: =(G9/B9)^(1/($G$3-$B$3))-1 -> 0.0035433816 | AQ9: =AG9-G9 -> -1144 | AR9: =AQ9/G9 -> -0.040716091 | AS9: =(AG9/G9)^(1/($AG$3-$G$3))-1 -> -0.0014323594
A10: Knox | B10: 46304 | C10: 47637 | D10: 54616 | E10: 61090 | F10: 62765 | G10: 62897 | H10: 64157 | I10: 65164 | J10: 61970 | K10: =I10-H10 -> 1007 | L10: =J10-$H10 -> -2187 | M10: 65339 | N10: 69227 | O10: 59572 | P10: =N10-$M10 -> 3888 | Q10: =O10-$M10 -> -5767 | R10: 67013 | S10: 74288 | T10: 56176 | U10: =S10-$R10 -> 7275 | V10: =T10-$R10 -> -10837 | W10: 68125 | X10: 80150 | Y10: 51978 | Z10: =X10-$W10 -> 12025 | AA10: =Y10-$W10 -> -16147 | AB10: 68957 | AC10: 86702 | AD10: 47091 | AE10: =AC10-$AB10 -> 17745 | AF10: =AD10-$AB10 -> -21866 | AG10: 69790 | AH10: 93868 | AI10: 41589 | AJ10: =AH10-$AG10 -> 24078 | AK10: =AI10-$AG10 -> -28201 | AM10: =G10-B10 -> 16593 | AN10: =AM10/B10 -> 0.35834917 | AO10: =(G10/B10)^(1/($G$3-$B$3))-1 -> 0.0074979729 | AQ10: =AG10-G10 -> 6893 | AR10: =AQ10/G10 -> 0.10959187 | AS10: =(AG10/G10)^(1/($AG$3-$G$3))-1 -> 0.0035923774
A11: Licking | B11: 120981 | C11: 129006 | D11: 146268 | E11: 166705 | F11: 178680 | G11: 180401 | H11: 190915 | I11: 189312 | J11: 176808 | K11: =I11-H11 -> -1603 | L11: =J11-$H11 -> -14107 | M11: 200710 | N11: 203164 | O11: 173324 | P11: =N11-$M11 -> 2454 | Q11: =O11-$M11 -> -27386 | R11: 216962 | S11: 219200 | T11: 167658 | U11: =S11-$R11 -> 2238 | V11: =T11-$R11 -> -49304 | W11: 225833 | X11: 237045 | Y11: 160181 | Z11: =X11-$W11 -> 11212 | AA11: =Y11-$W11 -> -65652 | AB11: 231017 | AC11: 256471 | AD11: 151123 | AE11: =AC11-$AB11 -> 25454 | AF11: =AD11-$AB11 -> -79894 | AG11: 236202 | AH11: 277319 | AI11: 140644 | AJ11: =AH11-$AG11 -> 41117 | AK11: =AI11-$AG11 -> -95558 | AM11: =G11-B11 -> 59420 | AN11: =AM11/B11 -> 0.4911515 | AO11: =(G11/B11)^(1/($G$3-$B$3))-1 -> 0.0097927268 | AQ11: =AG11-G11 -> 55801 | AR11: =AQ11/G11 -> 0.30931647 | AS11: =(AG11/G11)^(1/($AG$3-$G$3))-1 -> 0.0093366001
A12: Logan | B12: 39155 | C12: 42417 | D12: 45984 | E12: 45743 | F12: 46065 | G12: 46035 | H12: 46095 | I12: 47290 | J12: 44871 | K12: =I12-H12 -> 1195 | L12: =J12-$H12 -> -1224 | M12: 46407 | N12: 49351 | O12: 43377 | P12: =N12-$M12 -> 2944 | Q12: =O12-$M12 -> -3030 | R12: 46763 | S12: 51833 | T12: 41448 | U12: =S12-$R12 -> 5070 | V12: =T12-$R12 -> -5315 | W12: 47058 | X12: 54679 | Y12: 39156 | Z12: =X12-$W12 -> 7621 | AA12: =Y12-$W12 -> -7902 | AB12: 47335 | AC12: 57844 | AD12: 36544 | AE12: =AC12-$AB12 -> 10509 | AF12: =AD12-$AB12 -> -10791 | AG12: 47611 | AH12: 61297 | AI12: 33644 | AJ12: =AH12-$AG12 -> 13686 | AK12: =AI12-$AG12 -> -13967 | AM12: =G12-B12 -> 6880 | AN12: =AM12/B12 -> 0.17571191 | AO12: =(G12/B12)^(1/($G$3-$B$3))-1 -> 0.0039559468 | AQ12: =AG12-G12 -> 1576 | AR12: =AQ12/G12 -> 0.034234821 | AS12: =(AG12/G12)^(1/($AG$3-$G$3))-1 -> 0.0011614274
A13: Madison | B13: 33004 | C13: 37111 | D13: 40218 | E13: 43434 | F13: 43823 | G13: 44386 | H13: 46487 | I13: 49508 | J13: 42918 | K13: =I13-H13 -> 3021 | L13: =J13-$H13 -> -3569 | M13: 48833 | N13: 58168 | O13: 38616 | P13: =N13-$M13 -> 9335 | Q13: =O13-$M13 -> -10217 | R13: 51412 | S13: 68798 | T13: 32345 | U13: =S13-$R13 -> 17386 | V13: =T13-$R13 -> -19067 | W13: 53726 | X13: 81014 | Y13: 24486 | Z13: =X13-$W13 -> 27288 | AA13: =Y13-$W13 -> -29240 | AB13: 55905 | AC13: 94597 | AD13: 15261 | AE13: =AC13-$AB13 -> 38692 | AF13: =AD13-$AB13 -> -40644 | AG13: 58084 | AH13: 109400 | AI13: 4816 | AJ13: =AH13-$AG13 -> 51316 | AK13: =AI13-$AG13 -> -53268 | AM13: =G13-B13 -> 11382 | AN13: =AM13/B13 -> 0.34486729 | AO13: =(G13/B13)^(1/($G$3-$B$3))-1 -> 0.0072528913 | AQ13: =AG13-G13 -> 13698 | AR13: =AQ13/G13 -> 0.30861082 | AS13: =(AG13/G13)^(1/($AG$3-$G$3))-1 -> 0.0093178375
A14: Marion | B14: 67974 | C14: 64289 | D14: 66135 | E14: 66458 | F14: 65363 | G14: 65291 | H14: 65314 | I14: 66329 | J14: 63731 | K14: =I14-H14 -> 1015 | L14: =J14-$H14 -> -1583 | M14: 65160 | N14: 66651 | O14: 62754 | P14: =N14-$M14 -> 1491 | Q14: =O14-$M14 -> -2406 | R14: 65246 | S14: 66806 | T14: 61945 | U14: =S14-$R14 -> 1560 | V14: =T14-$R14 -> -3301 | W14: 65059 | X14: 66879 | Y14: 61217 | Z14: =X14-$W14 -> 1820 | AA14: =Y14-$W14 -> -3842 | AB14: 64732 | AC14: 66903 | AD14: 60539 | AE14: =AC14-$AB14 -> 2171 | AF14: =AD14-$AB14 -> -4193 | AG14: 64405 | AH14: 66892 | AI14: 59896 | AJ14: =AH14-$AG14 -> 2487 | AK14: =AI14-$AG14 -> -4509 | AM14: =G14-B14 -> -2683 | AN14: =AM14/B14 -> -0.039470974 | AO14: =(G14/B14)^(1/($G$3-$B$3))-1 -> -0.00098173919 | AQ14: =AG14-G14 -> -886 | AR14: =AQ14/G14 -> -0.013570017 | AS14: =(AG14/G14)^(1/($AG$3-$G$3))-1 -> -0.0004710246
A15: Morrow | B15: 26480 | C15: 27784 | D15: 31813 | E15: 34790 | F15: 34964 | G15: 35151 | H15: 36425 | I15: 37323 | J15: 34476 | K15: =I15-H15 -> 898 | L15: =J15-$H15 -> -1949 | M15: 37666 | N15: 41222 | O15: 32447 | P15: =N15-$M15 -> 3556 | Q15: =O15-$M15 -> -5219 | R15: 39338 | S15: 46050 | T15: 29489 | U15: =S15-$R15 -> 6712 | V15: =T15-$R15 -> -9849 | W15: 40519 | X15: 51621 | Y15: 25788 | Z15: =X15-$W15 -> 11102 | AA15: =Y15-$W15 -> -14731 | AB15: 41454 | AC15: 57832 | AD15: 21447 | AE15: =AC15-$AB15 -> 16378 | AF15: =AD15-$AB15 -> -20007 | AG15: 42389 | AH15: 64613 | AI15: 16536 | AJ15: =AH15-$AG15 -> 22224 | AK15: =AI15-$AG15 -> -25853 | AM15: =G15-B15 -> 8671 | AN15: =AM15/B15 -> 0.32745468 | AO15: =(G15/B15)^(1/($G$3-$B$3))-1 -> 0.0069327831 | AQ15: =AG15-G15 -> 7238 | AR15: =AQ15/G15 -> 0.20591164 | AS15: =(AG15/G15)^(1/($AG$3-$G$3))-1 -> 0.0064772954
A16: Perry | B16: 31032 | C16: 31596 | D16: 34099 | E16: 36037 | F16: 35439 | G16: 35460 | H16: 36859 | I16: 38560 | J16: 34761 | K16: =I16-H16 -> 1701 | L16: =J16-$H16 -> -2098 | M16: 37415 | N16: 41469 | O16: 32732 | P16: =N16-$M16 -> 4054 | Q16: =O16-$M16 -> -4683 | R16: 38131 | S16: 44979 | T16: 30102 | U16: =S16-$R16 -> 6848 | V16: =T16-$R16 -> -8029 | W16: 38662 | X16: 48989 | Y16: 26972 | Z16: =X16-$W16 -> 10327 | AA16: =Y16-$W16 -> -11690 | AB16: 39102 | AC16: 53437 | AD16: 23404 | AE16: =AC16-$AB16 -> 14335 | AF16: =AD16-$AB16 -> -15698 | AG16: 39542 | AH16: 58278 | AI16: 19442 | AJ16: =AH16-$AG16 -> 18736 | AK16: =AI16-$AG16 -> -20100 | AM16: =G16-B16 -> 4428 | AN16: =AM16/B16 -> 0.14269142 | AO16: =(G16/B16)^(1/($G$3-$B$3))-1 -> 0.0032586239 | AQ16: =AG16-G16 -> 4082 | AR16: =AQ16/G16 -> 0.11511562 | AS16: =(AG16/G16)^(1/($AG$3-$G$3))-1 -> 0.0037642428
A17: Pickaway | B17: 43662 | C17: 48257 | D17: 52808 | E17: 55740 | F17: 58628 | G17: 59333 | H17: 62355 | I17: 66029 | J17: 58005 | K17: =I17-H17 -> 3674 | L17: =J17-$H17 -> -4350 | M17: 65891 | N17: 77450 | O17: 53249 | P17: =N17-$M17 -> 11559 | Q17: =O17-$M17 -> -12642 | R17: 69716 | S17: 91360 | T17: 46004 | U17: =S17-$R17 -> 21644 | V17: =T17-$R17 -> -23712 | W17: 73212 | X17: 107272 | Y17: 36758 | Z17: =X17-$W17 -> 34060 | AA17: =Y17-$W17 -> -36454 | AB17: 76545 | AC17: 124906 | AD17: 25789 | AE17: =AC17-$AB17 -> 48361 | AF17: =AD17-$AB17 -> -50756 | AG17: 79877 | AH17: 144076 | AI17: 13285 | AJ17: =AH17-$AG17 -> 64199 | AK17: =AI17-$AG17 -> -66592 | AM17: =G17-B17 -> 15671 | AN17: =AM17/B17 -> 0.35891622 | AO17: =(G17/B17)^(1/($G$3-$B$3))-1 -> 0.007508229 | AQ17: =AG17-G17 -> 20544 | AR17: =AQ17/G17 -> 0.34624914 | AS17: =(AG17/G17)^(1/($AG$3-$G$3))-1 -> 0.01030523
... A19: Union | B19: 29536 | C19: 32010 | D19: 41338 | E19: 52464 | F19: 63077 | G19: 64971 | H19: 66408 | I19: 69664 | J19: 62368 | K19: =I19-H19 -> 3256 | L19: =J19-$H19 -> -4040 | M19: 72505 | N19: 80350 | O19: 63404 | P19: =N19-$M19 -> 7845 | Q19: =O19-$M19 -> -9101 | R19: 78933 | S19: 92220 | T19: 63255 | U19: =S19-$R19 -> 13287 | V19: =T19-$R19 -> -15678 | W19: 84983 | X19: 105075 | Y19: 62122 | Z19: =X19-$W19 -> 20092 | AA19: =Y19-$W19 -> -22861 | AB19: 90844 | AC19: 118792 | AD19: 60127 | AE19: =AC19-$AB19 -> 27948 | AF19: =AD19-$AB19 -> -30717 | AG19: 96705 | AH19: 133284 | AI19: 57356 | AJ19: =AH19-$AG19 -> 36579 | AK19: =AI19-$AG19 -> -39349 | AM19: =G19-B19 -> 35435 | AN19: =AM19/B19 -> 1.1997224 | AO19: =(G19/B19)^(1/($G$3-$B$3))-1 -> 0.01941363 | AQ19: =AG19-G19 -> 31734 | AR19: =AQ19/G19 -> 0.4884333 | AS19: =(AG19/G19)^(1/($AG$3-$G$3))-1 -> 0.013809101
A20: Total | B20: =SUM(B5:B19) -> 1571547 | C20: =SUM(C5:C19) -> 1719508 | D20: =SUM(D5:D19) -> 1950805 | E20: =SUM(E5:E19) -> 2186769 | F20: =SUM(F5:F19) -> 2421159 | G20: =SUM(G5:G19) -> 2431037 | H20: =SUM(H5:H19) -> 2555315 | I20: =SUM(I5:I19) -> 2597188 | J20: =SUM(J5:J19) -> 2445231 | K20: =I20-H20 -> 41873 | L20: =J20-$H20 -> -110084 | M20: =SUM(M5:M19) -> 2676926 | N20: =SUM(N5:N19) -> 2816613 | O20: =SUM(O5:O19) -> 2428110 | P20: =N20-$M20 -> 139687 | Q20: =O20-$M20 -> -248816 | R20: =SUM(R5:R19) -> 2827180 | S20: =SUM(S5:S19) -> 3068141 | T20: =SUM(T5:T19) -> 2378893 | U20: =S20-$R20 -> 240961 | V20: =T20-$R20 -> -448287 | W20: =SUM(W5:W19) -> 2944699 | X20: =SUM(X5:X19) -> 3345949 | Y20: =SUM(Y5:Y19) -> 2303397 | Z20: =X20-$W20 -> 401250 | AA20: =Y20-$W20 -> -641302 | AB20: =SUM(AB5:AB19) -> 3045854 | AC20: =SUM(AC5:AC19) -> 3646586 | AD20: =SUM(AD5:AD19) -> 2205068 | AE20: =AC20-$AB20 -> 600732 | AF20: =AD20-$AB20 -> -840786 | AG20: =SUM(AG5:AG19) -> 3147011 | AH20: =SUM(AH5:AH19) -> 3967683 | AI20: =SUM(AI5:AI19) -> 2086279 | AJ20: =AH20-$AG20 -> 820672 | AK20: =AI20-$AG20 -> -1060732 | AM20: =G20-B20 -> 859490 | AN20: =AM20/B20 -> 0.54690696 | AO20: =(G20/B20)^(1/($G$3-$B$3))-1 -> 0.010697236 | AQ20: =AG20-G20 -> 715974 | AR20: =AQ20/G20 -> 0.29451382 | AS20: =(AG20/G20)^(1/($AG$3-$G$3))-1 -> 0.0089409473
A22: 1 | B22: Historic population estimates are sourced from the Census Population Estimates Program
A23: 2 | B23: Forecasts are derived from historic patterns and major expected economic developments.
A24: 3 | B24: The confidence limits represent the highest and lowest expected population based exclusively on historic patterns. Unprecedented circumstances may cause the forecasted population to exceed these limits.
A25: 4 | B25: The confidence intervals represent the difference between the forecast and the upper confidence limit and the forecast and the lower confidence limit.
A26: 5 | B26: CAGR, or Compound Annual Growth Rate, calculated as (value at end of period / value at beginning of period) ^ (1/ number of years in period) - 1
B28: Updated January 9, 2023

Sheet Population Charts

Sheet Population by Age
C1: County Growth Projections Population by Age
A2: Population by Age Under 18
B3: Estimate | C3: Projections | K3: Share of Total Population
A4: COUNTY | B4: 2020 | C4: 2025 | D4: 2030 | E4: 2035 | F4: 2040 | G4: 2045 | H4: 2050 | K4: 2020 | L4: 2025 | M4: 2030 | N4: 2035 | O4: 2040 | P4: 2045 | Q4: 2050
A5: Delaware | B5: 53873 | C5: 57994 | D5: 62696 | E5: 68656 | F5: 74833 | G5: 80560 | H5: 85900 | K5: =B5/(B5+B25+B45) -> 0.25049986 | L5: =C5/(C5+C25+C45) -> 0.23477831 | M5: =D5/(D5+D25+D45) -> 0.22594456 | N5: =E5/(E5+E25+E45) -> 0.22085613 | O5: =F5/(F5+F25+F45) -> 0.21950504 | P5: =G5/(G5+G25+G45) -> 0.2181383 | Q5: =H5/(H5+H25+H45) -> 0.21599358
A6: Fairfield | B6: 37515 | C6: 39948 | D6: 42517 | E6: 45382 | F6: 47721 | G6: 49781 | H6: 51782 | K6: =B6/(B6+B26+B46) -> 0.23541482 | L6: =C6/(C6+C26+C46) -> 0.23612301 | M6: =D6/(D6+D26+D46) -> 0.23825855 | N6: =E6/(E6+E26+E46) -> 0.2403453 | O6: =F6/(F6+F26+F46) -> 0.24110283 | P6: =G6/(G6+G26+G46) -> 0.24118234 | Q6: =H6/(H6+H26+H46) -> 0.24098101
A7: Fayette | B7: 6614 | C7: 6617 | D7: 6510 | E7: 6617 | F7: 6856 | G7: 7091 | H7: 7290 | K7: =B7/(B7+B27+B47) -> 0.22854971 | L7: =C7/(C7+C27+C47) -> 0.22492267 | M7: =D7/(D7+D27+D47) -> 0.21692046 | N7: =E7/(E7+E27+E47) -> 0.21600183 | O7: =F7/(F7+F27+F47) -> 0.21960282 | P7: =G7/(G7+G27+G47) -> 0.22305757 | Q7: =H7/(H7+H27+H47) -> 0.22527812
A8: Franklin | B8: 309822 | C8: 324853 | D8: 336050 | E8: 348291 | F8: 359622 | G8: 366527 | H8: 375575 | K8: =B8/(B8+B28+B48) -> 0.23400223 | L8: =C8/(C8+C28+C48) -> 0.23368584 | M8: =D8/(D8+D28+D48) -> 0.23222467 | N8: =E8/(E8+E28+E48) -> 0.22916234 | O8: =F8/(F8+F28+F48) -> 0.22839654 | P8: =G8/(G8+G28+G48) -> 0.22621884 | Q8: =H8/(H8+H28+H48) -> 0.22544681
A9: Hocking | B9: 5996 | C9: 5896 | D9: 5871 | E9: 5798 | F9: 5758 | G9: 5674 | H9: 5611 | K9: =B9/(B9+B29+B49) -> 0.21415051 | L9: =C9/(C9+C29+C49) -> 0.21083497 | M9: =D9/(D9+D29+D49) -> 0.21147612 | N9: =E9/(E9+E29+E49) -> 0.20985197 | O9: =F9/(F9+F29+F49) -> 0.20993146 | P9: =G9/(G9+G29+G49) -> 0.20867966 | Q9: =H9/(H9+H29+H49) -> 0.2081772
A10: Knox | B10: 14942 | C10: 15282 | D10: 15553 | E10: 16138 | F10: 16567 | G10: 16856 | H10: 17132 | K10: =B10/(B10+B30+B50) -> 0.23806261 | L10: =C10/(C10+C30+C50) -> 0.23819692 | M10: =D10/(D10+D30+D50) -> 0.23803548 | N10: =E10/(E10+E30+E50) -> 0.24081895 | O10: =F10/(F10+F30+F50) -> 0.24318532 | P10: =G10/(G10+G30+G50) -> 0.24444219 | Q10: =H10/(H10+H30+H50) -> 0.2454793
A11: Licking | B11: 41136 | C11: 43793 | D11: 45865 | E11: 49473 | F11: 51486 | G11: 52211 | H11: 52940 | K11: =B11/(B11+B31+B51) -> 0.23022163 | L11: =C11/(C11+C31+C51) -> 0.2293848 | M11: =D11/(D11+D31+D51) -> 0.22851378 | N11: =E11/(E11+E31+E51) -> 0.22802611 | O11: =F11/(F11+F31+F51) -> 0.22798262 | P11: =G11/(G11+G31+G51) -> 0.22600501 | Q11: =H11/(H11+H31+H51) -> 0.22413019
A12: Logan | B12: 10341 | C12: 10139 | D12: 10008 | E12: 10026 | F12: 10017 | G12: 9940 | H12: 9832 | K12: =B12/(B12+B32+B52) -> 0.22448714 | L12: =C12/(C12+C32+C52) -> 0.21995878 | M12: =D12/(D12+D32+D52) -> 0.21565712 | N12: =E12/(E12+E32+E52) -> 0.21440027 | O12: =F12/(F12+F32+F52) -> 0.21286498 | P12: =G12/(G12+G32+G52) -> 0.20999261 | Q12: =H12/(H12+H32+H52) -> 0.2065069
A13: Madison | B13: 8858 | C13: 8999 | D13: 9104 | E13: 9399 | F13: 9511 | G13: 9886 | H13: 10300 | K13: =B13/(B13+B33+B53) -> 0.2021313 | L13: =C13/(C13+C33+C53) -> 0.193581 | M13: =D13/(D13+D33+D53) -> 0.18643131 | N13: =E13/(E13+E33+E53) -> 0.18281724 | O13: =F13/(F13+F33+F53) -> 0.17702788 | P13: =G13/(G13+G33+G53) -> 0.1768357 | Q13: =H13/(H13+H33+H53) -> 0.17732939
A14: Marion | B14: 13771 | C14: 13780 | D14: 13631 | E14: 13169 | F14: 12846 | G14: 12951 | H14: 13179 | K14: =B14/(B14+B34+B54) -> 0.21068494 | L14: =C14/(C14+C34+C54) -> 0.2109808 | M14: =D14/(D14+D34+D54) -> 0.20919276 | N14: =E14/(E14+E34+E54) -> 0.20183613 | O14: =F14/(F14+F34+F54) -> 0.19745154 | P14: =G14/(G14+G34+G54) -> 0.20007106 | Q14: =H14/(H14+H34+H54) -> 0.20462697
A15: Morrow | B15: 7666 | C15: 7443 | D15: 7509 | E15: 7845 | F15: 7991 | G15: 8011 | H15: 7952 | K15: =B15/(B15+B35+B55) -> 0.21925409 | L15: =C15/(C15+C35+C55) -> 0.20433768 | M15: =D15/(D15+D35+D55) -> 0.19935751 | N15: =E15/(E15+E35+E55) -> 0.19942549 | O15: =F15/(F15+F35+F55) -> 0.19721612 | P15: =G15/(G15+G35+G55) -> 0.19325035 | Q15: =H15/(H15+H35+H55) -> 0.18759584
A16: Perry | B16: 8095 | C16: 8339 | D16: 8346 | E16: 8415 | F16: 8520 | G16: 8595 | H16: 8700 | K16: =B16/(B16+B36+B56) -> 0.22842067 | L16: =C16/(C16+C36+C56) -> 0.22624054 | M16: =D16/(D16+D36+D56) -> 0.22306562 | N16: =E16/(E16+E36+E56) -> 0.22068658 | O16: =F16/(F16+F36+F56) -> 0.22037142 | P16: =G16/(G16+G36+G56) -> 0.21980973 | Q16: =H16/(H16+H36+H56) -> 0.22001922
... A19: Union | B19: 15142 | C19: 16083 | D19: 17995 | E19: 19992 | F19: 21635 | G19: 22646 | H19: 23535 | K19: =B19/(B19+B39+B59) -> 0.2400558 | L19: =C19/(C19+C39+C59) -> 0.24218468 | M19: =D19/(D19+D39+D59) -> 0.24818978 | N19: =E19/(E19+E39+E59) -> 0.2532781 | O19: =F19/(F19+F39+F59) -> 0.25458033 | P19: =G19/(G19+G39+G59) -> 0.24928449 | Q19: =H19/(H19+H39+H59) -> 0.24336901
A20: Total | B20: =SUM(B5:B19) -> 562305 | C20: =SUM(C5:C19) -> 587627 | D20: =SUM(D5:D19) -> 610020 | E20: =SUM(E5:E19) -> 637790 | F20: =SUM(F5:F19) -> 661930 | G20: =SUM(G5:G19) -> 679917 | H20: =SUM(H5:H19) -> 699676 | K20: =B20/(B20+B40+B60) -> 0.23224621 | L20: =C20/(C20+C40+C60) -> 0.22996265 | M20: =D20/(D20+D40+D60) -> 0.22788079 | N20: =E20/(E20+E40+E60) -> 0.22559229 | O20: =F20/(F20+F40+F60) -> 0.22478698 | P20: =G20/(G20+G40+G60) -> 0.22322705 | Q20: =H20/(H20+H40+H60) -> 0.22233033
A22: Population by Age 18 - 64
B23: Estimate | C23: Projections | K23: Share of Total Population
A24: COUNTY | B24: 2020 | C24: 2025 | D24: 2030 | E24: 2035 | F24: 2040 | G24: 2045 | H24: 2050 | K24: 2020 | L24: 2025 | M24: 2030 | N24: 2035 | O24: 2040 | P24: 2045 | Q24: 2050
A25: Delaware | B25: 129537 | C25: 147623 | D25: 162958 | E25: 179944 | F25: 195085 | G25: 210691 | H25: 226432 | K25: =B25/(B5+B25+B45) -> 0.60232398 | L25: =C25/(C5+C25+C45) -> 0.59762526 | M25: =D25/(D5+D25+D45) -> 0.5872699 | N25: =E25/(E5+E25+E45) -> 0.57885306 | O25: =F25/(F5+F25+F45) -> 0.57223606 | P25: =G25/(G5+G25+G45) -> 0.57050367 | Q25: =H25/(H5+H25+H45) -> 0.56935808
A26: Fairfield | B26: 95575 | C26: 99312 | D26: 102543 | E26: 108078 | F26: 114186 | G26: 120539 | H26: 126510 | K26: =B26/(B6+B26+B46) -> 0.59975401 | L26: =C26/(C6+C26+C46) -> 0.58700933 | M26: =D26/(D6+D26+D46) -> 0.57463477 | N26: =E26/(E6+E26+E46) -> 0.5723864 | O26: =F26/(F6+F26+F46) -> 0.57690675 | P26: =G26/(G6+G26+G46) -> 0.58399547 | Q26: =H26/(H6+H26+H46) -> 0.58874721
A27: Fayette | B27: 16976 | C27: 16999 | D27: 17272 | E27: 17603 | F27: 17905 | G27: 18289 | H27: 18699 | K27: =B27/(B7+B27+B47) -> 0.58661322 | L27: =C27/(C7+C27+C47) -> 0.57782386 | M27: =D27/(D7+D27+D47) -> 0.57552231 | N27: =E27/(E7+E27+E47) -> 0.57462297 | O27: =F27/(F7+F27+F47) -> 0.57351057 | P27: =G27/(G7+G27+G47) -> 0.5753067 | Q27: =H27/(H7+H27+H47) -> 0.57784302
A28: Franklin | B28: 846386 | C28: 871039 | D28: 897086 | E28: 945272 | F28: 985153 | G28: 1022277 | H28: 1051047 | K28: =B28/(B8+B28+B48) -> 0.63925807 | L28: =C28/(C8+C28+C48) -> 0.62658951 | M28: =D28/(D8+D28+D48) -> 0.61992412 | N28: =E28/(E8+E28+E48) -> 0.62195331 | O28: =F28/(F8+F28+F48) -> 0.62567233 | P28: =G28/(G8+G28+G48) -> 0.63094483 | Q28: =H28/(H8+H28+H48) -> 0.63091312
A29: Hocking | B29: 16420 | C29: 15903 | D29: 15291 | E29: 15073 | F29: 14936 | G29: 14975 | H29: 15040 | K29: =B29/(B9+B29+B49) -> 0.58644952 | L29: =C29/(C9+C29+C49) -> 0.56867513 | M29: =D29/(D9+D29+D49) -> 0.55078885 | N29: =E29/(E9+E29+E49) -> 0.54554997 | O29: =F29/(F9+F29+F49) -> 0.54455301 | P29: =G29/(G9+G29+G49) -> 0.55075395 | Q29: =H29/(H9+H29+H49) -> 0.55800838
A30: Knox | B30: 35971 | C30: 35389 | D30: 35251 | E30: 35892 | F30: 36799 | G30: 37802 | H30: 38702 | K30: =B30/(B10+B30+B50) -> 0.57310603 | L30: =C30/(C10+C30+C50) -> 0.55159998 | M30: =D30/(D10+D30+D50) -> 0.53950933 | N30: =E30/(E10+E30+E50) -> 0.53559757 | O30: =F30/(F10+F30+F50) -> 0.54016881 | P30: =G30/(G10+G30+G50) -> 0.5481967 | Q30: =H30/(H10+H30+H50) -> 0.55454936
A31: Licking | B31: 106797 | C31: 111273 | D31: 114735 | E31: 123803 | F31: 130275 | G31: 135753 | H31: 140179 | K31: =B31/(B11+B31+B51) -> 0.5976998 | L31: =C31/(C11+C31+C51) -> 0.58284053 | M31: =D31/(D11+D31+D51) -> 0.57164566 | N31: =E31/(E11+E31+E51) -> 0.57062066 | O31: =F31/(F11+F31+F51) -> 0.57686432 | P31: =G31/(G11+G31+G51) -> 0.58763208 | Q31: =H31/(H11+H31+H51) -> 0.59347084
A32: Logan | B32: 26898 | C32: 26159 | D32: 25765 | E32: 25825 | F32: 26082 | G32: 26530 | H32: 27062 | K32: =B32/(B12+B32+B52) -> 0.58391403 | L32: =C32/(C12+C32+C52) -> 0.5675019 | M32: =D32/(D12+D32+D52) -> 0.55519641 | N32: =E32/(E12+E32+E52) -> 0.55225285 | O32: =F32/(F12+F32+F52) -> 0.5542522 | P32: =G32/(G12+G32+G52) -> 0.56047322 | Q32: =H32/(H12+H32+H52) -> 0.56839806
A33: Madison | B33: 27804 | C33: 28927 | D33: 29783 | E33: 31056 | F33: 32561 | G33: 34078 | H33: 35517 | K33: =B33/(B13+B33+B53) -> 0.63446136 | L33: =C33/(C13+C33+C53) -> 0.62225999 | M33: =D33/(D13+D33+D53) -> 0.60989495 | N33: =E33/(E13+E33+E53) -> 0.60406131 | O33: =F33/(F13+F33+F53) -> 0.60605666 | P33: =G33/(G13+G33+G53) -> 0.60956981 | Q33: =H33/(H13+H33+H53) -> 0.61147648
A34: Marion | B34: 39419 | C34: 38144 | D34: 37481 | E34: 38061 | F34: 38725 | G34: 39032 | H34: 39029 | K34: =B34/(B14+B34+B54) -> 0.60307819 | L34: =C34/(C14+C34+C54) -> 0.58400955 | M34: =D34/(D14+D34+D54) -> 0.57521486 | N34: =E34/(E14+E34+E54) -> 0.58334611 | O34: =F34/(F14+F34+F54) -> 0.59522895 | P34: =G34/(G14+G34+G54) -> 0.60297843 | Q34: =H34/(H14+H34+H54) -> 0.60599332
A35: Morrow | B35: 20820 | C35: 21202 | D35: 21385 | E35: 21937 | F35: 22481 | G35: 23148 | H35: 23961 | K35: =B35/(B15+B35+B55) -> 0.59546963 | L35: =C35/(C15+C35+C55) -> 0.58207275 | M35: =D35/(D15+D35+D55) -> 0.56775341 | N35: =E35/(E15+E35+E55) -> 0.55765418 | O35: =F35/(F15+F35+F55) -> 0.55482613 | P35: =G35/(G15+G35+G55) -> 0.55840208 | Q35: =H35/(H15+H35+H55) -> 0.56526457
A36: Perry | B36: 21118 | C36: 21180 | D36: 21008 | E36: 21171 | F36: 21557 | G36: 21997 | H36: 22374 | K36: =B36/(B16+B36+B56) -> 0.59589718 | L36: =C36/(C16+C36+C56) -> 0.57462221 | M36: =D36/(D16+D36+D56) -> 0.56148604 | N36: =E36/(E16+E36+E56) -> 0.55521754 | O36: =F36/(F16+F36+F56) -> 0.55757591 | P36: =G36/(G16+G36+G56) -> 0.56255435 | Q36: =H36/(H16+H36+H56) -> 0.56582874
... A39: Union | B39: 39626 | C39: 40694 | D39: 43147 | E39: 46320 | F39: 49981 | G39: 54246 | H39: 58482 | K39: =B39/(B19+B39+B59) -> 0.62821631 | L39: =C39/(C19+C39+C59) -> 0.61278762 | M39: =D39/(D19+D39+D59) -> 0.59508999 | N39: =E39/(E19+E39+E59) -> 0.5868268 | O39: =F39/(F19+F39+F59) -> 0.58812939 | P39: =G39/(G19+G39+G59) -> 0.59713355 | Q39: =H39/(H19+H39+H59) -> 0.60474639
A40: Total | B40: =SUM(B25:B39) -> 1507157 | C40: =SUM(C25:C39) -> 1557967 | D40: =SUM(D25:D39) -> 1608625 | E40: =SUM(E25:E39) -> 1696702 | F40: =SUM(F25:F39) -> 1774942 | G40: =SUM(G25:G39) -> 1850655 | H40: =SUM(H25:H39) -> 1916531 | K40: =B40/(B20+B40+B60) -> 0.62249402 | L40: =C40/(C20+C40+C60) -> 0.60969665 | M40: =D40/(D20+D40+D60) -> 0.60092248 | N40: =E40/(E20+E40+E60) -> 0.60013936 | O40: =F40/(F20+F40+F60) -> 0.60275838 | P40: =G40/(G20+G40+G60) -> 0.60759807 | Q40: =H40/(H20+H40+H60) -> 0.60900041
A42: Population by Age 65 and older
B43: Estimate | C43: Projections | K43: Share of Total Population
A44: COUNTY | B44: 2020 | C44: 2025 | D44: 2030 | E44: 2035 | F44: 2040 | G44: 2045 | H44: 2050 | K44: 2020 | L44: 2025 | M44: 2030 | N44: 2035 | O44: 2040 | P44: 2045 | Q44: 2050
A45: Delaware | B45: 31652 | C45: 41399 | D45: 51830 | E45: 62263 | F45: 70999 | G45: 78056 | H45: 85365 | K45: =B45/(B45+B25+B5) -> 0.14717616 | L45: =C45/(C45+C25+C5) -> 0.16759643 | M45: =D45/(D45+D25+D5) -> 0.18678554 | N45: =E45/(E45+E25+E5) -> 0.2002908 | O45: =F45/(F45+F25+F5) -> 0.2082589 | P45: =G45/(G45+G25+G5) -> 0.21135803 | Q45: =H45/(H45+H25+H5) -> 0.21464834
A46: Fairfield | B46: 26267 | C46: 29923 | D46: 33389 | E46: 35360 | F46: 36021 | G46: 36084 | H46: 36588 | K46: =B46/(B46+B26+B6) -> 0.16483117 | L46: =C46/(C46+C26+C6) -> 0.17686765 | M46: =D46/(D46+D26+D6) -> 0.18710668 | N46: =E46/(E46+E26+E6) -> 0.1872683 | O46: =F46/(F46+F26+F6) -> 0.18199042 | P46: =G46/(G46+G26+G6) -> 0.17482219 | Q46: =H46/(H46+H26+H6) -> 0.17027178
...

Sheet Group Quarters and Households
C1: County Growth Projections Population in Group Quarters and Households
A2: Population in Group Quarters (1)
B3: Estimate | C3: Projections | K3: Share of Total Population (2)
A4: COUNTY | B4: 2020 | C4: 2025 | D4: 2030 | E4: 2035 | F4: 2040 | G4: 2045 | H4: 2050 | K4: 2020 | L4: 2025 | M4: 2030 | N4: 2035 | O4: 2040 | P4: 2045 | Q4: 2050
A5: Delaware | B5: 2739 | C5: 3160 | D5: 3549 | E5: 3976 | F5: 4361 | G5: 4724 | H5: 5087 | K5: =B5/(B5+B25) -> 0.012795717 | L5: =C5/(C5+C25) -> 0.012797719 | M5: =D5/(D5+D25) -> 0.012794814 | N5: =E5/(E5+E25) -> 0.012794686 | O5: =F5/(F5+F25) -> 0.012795948 | P5: =G5/(G5+G25) -> 0.012795441 | Q5: =H5/(H5+H25) -> 0.012795134
A6: Fairfield | B6: 3095 | C6: 3295 | D6: 3475 | E6: 3677 | F6: 3855 | G6: 4020 | H6: 4185 | K6: =B6/(B6+B26) -> 0.019479866 | L6: =C6/(C6+C26) -> 0.019483322 | M6: =D6/(D6+D26) -> 0.019482303 | N6: =E6/(E6+E26) -> 0.019481724 | O6: =F6/(F6+F26) -> 0.019483276 | P6: =G6/(G6+G26) -> 0.01948118 | Q6: =H6/(H6+H26) -> 0.019479794
A7: Fayette | B7: 320 | C7: 326 | D7: 332 | E7: 339 | F7: 345 | G7: 352 | H7: 358 | K7: =B7/(B7+B27) -> 0.011058506 | L7: =C7/(C7+C27) -> 0.011092586 | M7: =D7/(D7+D27) -> 0.011080332 | N7: =E7/(E7+E27) -> 0.011084589 | O7: =F7/(F7+F27) -> 0.011067625 | P7: =G7/(G7+G27) -> 0.011086963 | Q7: =H7/(H7+H27) -> 0.011074677
A8: Franklin | B8: 29452 | C8: 30928 | D8: 32195 | E8: 33814 | F8: 35031 | G8: 36047 | H8: 37064 | K8: =B8/(B8+B28) -> 0.022250376 | L8: =C8/(C8+C28) -> 0.022249944 | M8: =D8/(D8+D28) -> 0.022250004 | N8: =E8/(E8+E28) -> 0.022252069 | O8: =F8/(F8+F28) -> 0.022252699 | P8: =G8/(G8+G28) -> 0.022254092 | Q8: =H8/(H8+H28) -> 0.022254913
A9: Hocking | B9: 470 | C9: 468 | D9: 465 | E9: 463 | F9: 459 | G9: 455 | H9: 451 | K9: =B9/(B9+B29) -> 0.016759976 | L9: =C9/(C9+C29) -> 0.016748381 | M9: =D9/(D9+D29) -> 0.016768238 | N9: =E9/(E9+E29) -> 0.01677901 | O9: =F9/(F9+F29) -> 0.016756717 | P9: =G9/(G9+G29) -> 0.016755045 | Q9: =H9/(H9+H29) -> 0.016751476
A10: Knox | B10: 3768 | C10: 3855 | D10: 3926 | E10: 4026 | F10: 4093 | G10: 4143 | H10: 4193 | K10: =B10/(B10+B30) -> 0.060016246 | L10: =C10/(C10+C30) -> 0.059968266 | M10: =D10/(D10+D30) -> 0.059936186 | N10: =E10/(E10+E30) -> 0.059910714 | O10: =F10/(F10+F30) -> 0.059920652 | P10: =G10/(G10+G30) -> 0.059939236 | Q10: =H10/(H10+H30) -> 0.059953959
A11: Licking | B11: 4027 | C11: 4307 | D11: 4528 | E11: 4895 | F11: 5095 | G11: 5212 | H11: 5329 | K11: =B11/(B11+B31) -> 0.022561109 | L11: =C11/(C11+C31) -> 0.022561314 | M11: =D11/(D11+D31) -> 0.02256025 | N11: =E11/(E11+E31) -> 0.022561971 | O11: =F11/(F11+F31) -> 0.022562218 | P11: =G11/(G11+G31) -> 0.022565115 | Q11: =H11/(H11+H31) -> 0.022567026
A12: Logan | B12: 490 | C12: 489 | D12: 493 | E12: 496 | F12: 500 | G12: 503 | H12: 505 | K12: =B12/(B12+B32) -> 0.010620773 | L12: =C12/(C12+C32) -> 0.010618893 | M12: =D12/(D12+D32) -> 0.010638987 | N12: =E12/(E12+E32) -> 0.010623715 | O12: =F12/(F12+F32) -> 0.010641921 | P12: =G12/(G12+G32) -> 0.010642124 | Q12: =H12/(H12+H32) -> 0.01062107
A13: Madison | B13: 5229 | C13: 5547 | D13: 5827 | E13: 6135 | F13: 6411 | G13: 6671 | H13: 6931 | K13: =B13/(B13+B33) -> 0.11926919 | L13: =C13/(C13+C33) -> 0.11912636 | M13: =D13/(D13+D33) -> 0.11897178 | N13: =E13/(E13+E33) -> 0.11890457 | O13: =F13/(F13+F33) -> 0.11896235 | P13: =G13/(G13+G33) -> 0.11901873 | Q13: =H13/(H13+H33) -> 0.11904639
A14: Marion | B14: 5667 | C14: 5663 | D14: 5650 | E14: 5658 | F14: 5641 | G14: 5613 | H14: 5585 | K14: =B14/(B14+B34) -> 0.086646077 | L14: =C14/(C14+C34) -> 0.086534641 | M14: =D14/(D14+D34) -> 0.086499893 | N14: =E14/(E14+E34) -> 0.086587904 | O14: =F14/(F14+F34) -> 0.086664618 | P14: =G14/(G14+G34) -> 0.08669931 | Q14: =H14/(H14+H34) -> 0.086700716
A15: Morrow | B15: 275 | C15: 286 | D15: 296 | E15: 309 | F15: 319 | G15: 326 | H15: 333 | K15: =B15/(B15+B35) -> 0.0078701849 | L15: =C15/(C15+C35) -> 0.0078588701 | M15: =D15/(D15+D35) -> 0.0078689919 | N15: =E15/(E15+E35) -> 0.0078669993 | O15: =F15/(F15+F35) -> 0.0078856945 | P15: =G15/(G15+G35) -> 0.0078770599 | Q15: =H15/(H15+H35) -> 0.0078689919
A16: Perry | B16: 338 | C16: 352 | D16: 358 | E16: 365 | F16: 370 | G16: 374 | H16: 378 | K16: =B16/(B16+B36) -> 0.0095482923 | L16: =C16/(C16+C36) -> 0.009557945 | M16: =D16/(D16+D36) -> 0.009580646 | N16: =E16/(E16+E36) -> 0.0095868463 | O16: =F16/(F16+F36) -> 0.0095842507 | P16: =G16/(G16+G36) -> 0.0095779553 | Q16: =H16/(H16+H36) -> 0.0095715588
... A19: Union | B19: 3536 | C19: 3740 | D19: 4083 | E19: 4445 | F19: 4786 | G19: 5116 | H19: 5446 | K19: =B19/(B19+B39) -> 0.056383844 | L19: =C19/(C19+C39) -> 0.056340574 | M19: =D19/(D19+D39) -> 0.05627998 | N19: =E19/(E19+E39) -> 0.056249446 | O19: =F19/(F19+F39) -> 0.0562536 | P19: =G19/(G19+G39) -> 0.056285963 | Q19: =H19/(H19+H39) -> 0.056315017
A20: Total | B20: =SUM(B5:B19) -> 69903 | C20: =SUM(C5:C19) -> 73176 | D20: =SUM(D5:D19) -> 76188 | E20: =SUM(E5:E19) -> 79887 | F20: =SUM(F5:F19) -> 82800 | G20: =SUM(G5:G19) -> 85321 | H20: =SUM(H5:H19) -> 87840 | K20: =B20/(B20+B40) -> 0.028897932 | L20: =C20/(C20+C40) -> 0.028636626 | M20: =D20/(D20+D40) -> 0.028459334 | N20: =E20/(E20+E40) -> 0.028256199 | O20: =F20/(F20+F40) -> 0.028119718 | P20: =G20/(G20+G40) -> 0.028015911 | Q20: =H20/(H20+H40) -> 0.027917043
A22: Population in Households
B23: Estimate | C23: Projections | J23: Share of Total Population
A24: COUNTY | B24: 2020 | C24: 2025 | D24: 2030 | E24: 2035 | F24: 2040 | G24: 2045 | H24: 2050 | K24: 2020 | L24: 2025 | M24: 2030 | N24: 2035 | O24: 2040 | P24: 2045 | Q24: 2050
A25: Delaware | B25: 211317 | C25: 243759 | D25: 273829 | E25: 306778 | F25: 336450 | G25: 364470 | H25: 392486 | J25: 335024.16 | K25: =B25/(B25+B5) -> 0.98720428 | L25: =C25/(C25+C5) -> 0.98720228 | M25: =D25/(D25+D5) -> 0.98720519 | N25: =E25/(E25+E5) -> 0.98720531 | O25: =F25/(F25+F5) -> 0.98720405 | P25: =G25/(G25+G5) -> 0.98720456 | Q25: =H25/(H25+H5) -> 0.98720487
A26: Fairfield | B26: 155787 | C26: 165824 | D26: 174892 | E26: 185064 | F26: 194007 | G26: 202333 | H26: 210653 | J26: 215587.21 | K26: =B26/(B26+B6) -> 0.98052013 | L26: =C26/(C26+C6) -> 0.98051668 | M26: =D26/(D26+D6) -> 0.9805177 | N26: =E26/(E26+E6) -> 0.98051828 | O26: =F26/(F26+F6) -> 0.98051672 | P26: =G26/(G26+G6) -> 0.98051882 | Q26: =H26/(H26+H6) -> 0.98052021
A27: Fayette | B27: 28617 | C27: 29063 | D27: 29631 | E27: 30244 | F27: 30827 | G27: 31397 | H27: 31968 | J27: 31149.92 | K27: =B27/(B27+B7) -> 0.98894149 | L27: =C27/(C27+C7) -> 0.98890741 | M27: =D27/(D27+D7) -> 0.98891967 | N27: =E27/(E27+E7) -> 0.98891541 | O27: =F27/(F27+F7) -> 0.98893238 | P27: =G27/(G27+G7) -> 0.98891304 | Q27: =H27/(H27+H7) -> 0.98892532
A28: Franklin | B28: 1294211 | C28: 1359098 | D28: 1414771 | E28: 1485775 | F28: 1539205 | G28: 1583745 | H28: 1628366 | J28: 1647056.5 | K28: =B28/(B28+B8) -> 0.97774962 | L28: =C28/(C28+C8) -> 0.97775006 | M28: =D28/(D28+D8) -> 0.97775 | N28: =E28/(E28+E8) -> 0.97774793 | O28: =F28/(F28+F8) -> 0.9777473 | P28: =G28/(G28+G8) -> 0.97774591 | Q28: =H28/(H28+H8) -> 0.97774509
A29: Hocking | B29: 27573 | C29: 27475 | D29: 27266 | E29: 27131 | F29: 26933 | G29: 26701 | H29: 26472 | J29: 22835.651 | K29: =B29/(B29+B9) -> 0.98324002 | L29: =C29/(C29+C9) -> 0.98325162 | M29: =D29/(D29+D9) -> 0.98323176 | N29: =E29/(E29+E9) -> 0.98322099 | O29: =F29/(F29+F9) -> 0.98324328 | P29: =G29/(G29+G9) -> 0.98324496 | Q29: =H29/(H29+H9) -> 0.98324852
A30: Knox | B30: 59015 | C30: 60429 | D30: 61577 | E30: 63174 | F30: 64214 | G30: 64977 | H30: 65744 | J30: 73588.473 | K30: =B30/(B30+B10) -> 0.93998375 | L30: =C30/(C30+C10) -> 0.94003173 | M30: =D30/(D30+D10) -> 0.94006381 | N30: =E30/(E30+E10) -> 0.94008929 | O30: =F30/(F30+F10) -> 0.94007935 | P30: =G30/(G30+G10) -> 0.94006076 | Q30: =H30/(H30+H10) -> 0.94004604
A31: Licking | B31: 174466 | C31: 186595 | D31: 196179 | E31: 212063 | F31: 220725 | G31: 225764 | H31: 230812 | J31: 227620.99 | K31: =B31/(B31+B11) -> 0.97743889 | L31: =C31/(C31+C11) -> 0.97743869 | M31: =D31/(D31+D11) -> 0.97743975 | N31: =E31/(E31+E11) -> 0.97743803 | O31: =F31/(F31+F11) -> 0.97743778 | P31: =G31/(G31+G11) -> 0.97743489 | Q31: =H31/(H31+H11) -> 0.97743297
A32: Logan | B32: 45646 | C32: 45561 | D32: 45846 | E32: 46192 | F32: 46484 | G32: 46762 | H32: 47042 | J32: 50681.028 | K32: =B32/(B32+B12) -> 0.98937923 | L32: =C32/(C32+C12) -> 0.98938111 | M32: =D32/(D32+D12) -> 0.98936101 | N32: =E32/(E32+E12) -> 0.98937629 | O32: =F32/(F32+F12) -> 0.98935808 | P32: =G32/(G32+G12) -> 0.98935788 | Q32: =H32/(H32+H12) -> 0.98937893
A33: Madison | B33: 38613 | C33: 41017 | D33: 43151 | E33: 45461 | F33: 47480 | G33: 49379 | H33: 51290 | J33: 46454.033 | K33: =B33/(B33+B13) -> 0.88073081 | L33: =C33/(C33+C13) -> 0.88087364 | M33: =D33/(D33+D13) -> 0.88102822 | N33: =E33/(E33+E13) -> 0.88109543 | O33: =F33/(F33+F13) -> 0.88103765 | P33: =G33/(G33+G13) -> 0.88098127 | Q33: =H33/(H33+H13) -> 0.88095361
A34: Marion | B34: 59737 | C34: 59779 | D34: 59668 | E34: 59686 | F34: 59449 | G34: 59128 | H34: 58832 | J34: 52417.469 | K34: =B34/(B34+B14) -> 0.91335392 | L34: =C34/(C34+C14) -> 0.91346536 | M34: =D34/(D34+D14) -> 0.91350011 | N34: =E34/(E34+E14) -> 0.9134121 | O34: =F34/(F34+F14) -> 0.91333538 | P34: =G34/(G34+G14) -> 0.91330069 | Q34: =H34/(H34+H14) -> 0.91329928
A35: Morrow | B35: 34667 | C35: 36106 | D35: 37320 | E35: 38969 | F35: 40134 | G35: 41060 | H35: 41985 | J35: 42771.173 | K35: =B35/(B35+B15) -> 0.99212982 | L35: =C35/(C35+C15) -> 0.99214113 | M35: =D35/(D35+D15) -> 0.99213101 | N35: =E35/(E35+E15) -> 0.992133 | O35: =F35/(F35+F15) -> 0.99211431 | P35: =G35/(G35+G15) -> 0.99212294 | Q35: =H35/(H35+H15) -> 0.99213101
A36: Perry | B36: 35061 | C36: 36476 | D36: 37009 | E36: 37708 | F36: 38235 | G36: 38674 | H36: 39114 | J36: 36375.546 | K36: =B36/(B36+B16) -> 0.99045171 | L36: =C36/(C36+C16) -> 0.99044205 | M36: =D36/(D36+D16) -> 0.99041935 | N36: =E36/(E36+E16) -> 0.99041315 | O36: =F36/(F36+F16) -> 0.99041575 | P36: =G36/(G36+G16) -> 0.99042204 | Q36: =H36/(H36+H16) -> 0.99042844
... A39: Union | B39: 59177 | C39: 62642 | D39: 68465 | E39: 74578 | F39: 80293 | G39: 85777 | H39: 91260 | J39: 89025.156 | K39: =B39/(B39+B19) -> 0.94361616 | L39: =C39/(C39+C19) -> 0.94365943 | M39: =D39/(D39+D19) -> 0.94372002 | N39: =E39/(E39+E19) -> 0.94375055 | O39: =F39/(F39+F19) -> 0.9437464 | P39: =G39/(G39+G19) -> 0.94371404 | Q39: =H39/(H39+H19) -> 0.94368498
A40: Total | B40: =SUM(B25:B39) -> 2349059 | C40: =SUM(C25:C39) -> 2482153 | D40: =SUM(D25:D39) -> 2600895 | E40: =SUM(E25:E39) -> 2747351 | F40: =SUM(F25:F39) -> 2861753 | G40: =SUM(G25:G39) -> 2960127 | H40: =SUM(H25:H39) -> 3058625 | K40: =B40/(B40+B20) -> 0.97110207 | L40: =C40/(C40+C20) -> 0.97136337 | M40: =D40/(D40+D20) -> 0.97154067 | N40: =E40/(E40+E20) -> 0.9717438 | O40: =F40/(F40+F20) -> 0.97188028 | P40: =G40/(G40+G20) -> 0.97198409 | Q40: =H40/(H40+H20) -> 0.97208296
A43: 1 | B43: Group quarters are non-household living arrangements such as dormitories, nursing homes, or correctional facilities
A44: 2 | B44: Group quarters is assumed as a fixed share of the total population in the future.
B46: Updated May 12, 2023

Sheet Household Population by Age
C1: County Growth Projections Household Population by Age
A2: Household Population by Age Under 18
B3: Estimate | C3: Projections | L3: Share of Total Household Population
A4: COUNTY | B4: 2020 | C4: 2025 | D4: 2030 | E4: 2035 | F4: 2040 | G4: 2045 | H4: 2050 | L4: 2020 | M4: 2025 | N4: 2030 | O4: 2035 | P4: 2040 | Q4: 2045 | R4: 2050
A5: Delaware | B5: 53459.584 | C5: 57802.211 | D5: 62488.397 | E5: 68429.156 | F5: 74584.974 | G5: 80292.682 | H5: 85615.513 | L5: =B5/(B5+B25+B45) -> 0.25298288 | M5: =C5/(C5+C25+C45) -> 0.23670514 | N5: =D5/(D5+D25+D45) -> 0.22752259 | O5: =E5/(E5+E25+E45) -> 0.22216753 | P5: =F5/(F5+F25+F45) -> 0.22063949 | Q5: =G5/(G5+G25+G45) -> 0.21913284 | R5: =H5/(H5+H25+H45) -> 0.21686672
A6: Fairfield | B6: 37338.736 | C6: 39868.978 | D6: 42433.106 | E6: 45292.284 | F6: 47626.957 | G6: 49682.842 | H6: 51679.733 | L6: =B6/(B6+B26+B46) -> 0.23901686 | M6: =C6/(C6+C26+C46) -> 0.23948928 | N6: =D6/(D6+D26+D46) -> 0.24145938 | O6: =E6/(E6+E26+E46) -> 0.24337475 | P6: =F6/(F6+F26+F46) -> 0.24398431 | Q6: =G6/(G6+G26+G46) -> 0.24392957 | R6: =H6/(H6+H26+H46) -> 0.24360111
A7: Fayette | B7: 6616.6189 | C7: 6617.3337 | D7: 6510.3178 | E7: 6616.8701 | F7: 6856.0954 | G7: 7091.3458 | H7: 7290.1283 | L7: =B7/(B7+B27+B47) -> 0.25137219 | M7: =C7/(C7+C27+C47) -> 0.2470076 | N7: =D7/(D7+D27+D47) -> 0.23775903 | O7: =E7/(E7+E27+E47) -> 0.2362746 | P7: =F7/(F7+F27+F47) -> 0.23979908 | Q7: =G7/(G7+G27+G47) -> 0.2431791 | R7: =H7/(H7+H27+H47) -> 0.24520293
A8: Franklin | B8: 309386.52 | C8: 324447.44 | D8: 335630.41 | E8: 347855.7 | F8: 359172 | G8: 366068.57 | H8: 375105.21 | L8: =B8/(B8+B28+B48) -> 0.23424336 | M8: =C8/(C8+C28+C48) -> 0.23390477 | N8: =D8/(D8+D28+D48) -> 0.23242443 | O8: =E8/(E8+E28+E48) -> 0.22933827 | P8: =F8/(F8+F28+F48) -> 0.22855768 | Q8: =G8/(G8+G28+G48) -> 0.22636719 | R8: =H8/(H8+H28+H48) -> 0.22558445
A9: Hocking | B9: 6007.1658 | C9: 5895.6057 | D9: 5871.457 | E9: 5798.3794 | F9: 5758.1539 | G9: 5674.3268 | H9: 5610.5868 | L9: =B9/(B9+B29+B49) -> 0.23630722 | M9: =C9/(C9+C29+C49) -> 0.23269678 | N9: =D9/(D9+D29+D49) -> 0.23361545 | O9: =E9/(E9+E29+E49) -> 0.23193518 | P9: =F9/(F9+F29+F49) -> 0.23219299 | Q9: =G9/(G9+G29+G49) -> 0.23102996 | R9: =H9/(H9+H29+H49) -> 0.23066053
A10: Knox | B10: 14854.416 | C10: 15203.266 | D10: 15471.644 | E10: 16053.808 | F10: 16481.425 | G10: 16768.684 | H10: 17042.833 | L10: =B10/(B10+B30+B50) -> 0.24751172 | M10: =C10/(C10+C30+C50) -> 0.24741275 | N10: =D10/(D10+D30+D50) -> 0.24703642 | O10: =E10/(E10+E30+E50) -> 0.24967042 | P10: =F10/(F10+F30+F50) -> 0.25197102 | Q10: =G10/(G10+G30+G50) -> 0.2531466 | R10: =H10/(H10+H30+H50) -> 0.25409758
A11: Licking | B11: 41091.69 | C11: 43785.055 | D11: 45856.897 | E11: 49464.023 | F11: 51476.737 | G11: 52202.186 | H11: 52930.902 | L11: =B11/(B11+B31+B51) -> 0.23363082 | M11: =C11/(C11+C31+C51) -> 0.23255534 | N11: =D11/(D11+D31+D51) -> 0.23151514 | O11: =E11/(E11+E31+E51) -> 0.23079087 | P11: =F11/(F11+F31+F51) -> 0.23063571 | Q11: =G11/(G11+G31+G51) -> 0.228577 | R11: =H11/(H11+H31+H51) -> 0.22662269
A12: Logan | B12: 10295.892 | C12: 10076.059 | D12: 9945.721 | E12: 9964.2687 | F12: 9955.3453 | G12: 9877.5064 | H12: 9771.3658 | L12: =B12/(B12+B32+B52) -> 0.23692137 | M12: =C12/(C12+C32+C52) -> 0.23215122 | N12: =D12/(D12+D32+D52) -> 0.22750757 | O12: =E12/(E12+E32+E52) -> 0.22609069 | P12: =F12/(F12+F32+F52) -> 0.22438626 | Q12: =G12/(G12+G32+G52) -> 0.22125048 | R12: =H12/(H12+H32+H52) -> 0.21752334
A13: Madison | B13: 8858.5688 | C13: 8998.9676 | D13: 9103.5586 | E13: 9398.689 | F13: 9510.6772 | G13: 9885.7182 | H13: 10299.994 | L13: =B13/(B13+B33+B53) -> 0.2150399 | M13: =C13/(C13+C33+C53) -> 0.20518418 | N13: =D13/(D13+D33+D53) -> 0.19702967 | O13: =E13/(E13+E33+E53) -> 0.1926632 | P13: =F13/(F13+F33+F53) -> 0.18612986 | Q13: =G13/(G13+G33+G53) -> 0.18555669 | R13: =H13/(H13+H33+H53) -> 0.18573608
A14: Marion | B14: 13725.13 | C14: 13735.254 | D14: 13585.835 | E14: 13125.757 | F14: 12804.025 | G14: 12909.088 | H14: 13136.203 | L14: =B14/(B14+B34+B54) -> 0.21895398 | M14: =C14/(C14+C34+C54) -> 0.2192729 | N14: =D14/(D14+D34+D54) -> 0.21742206 | O14: =E14/(E14+E34+E54) -> 0.20976375 | P14: =F14/(F14+F34+F54) -> 0.20523218 | Q14: =G14/(G14+G34+G54) -> 0.20800644 | R14: =H14/(H14+H34+H54) -> 0.21279062
A15: Morrow | B15: 7661.3221 | C15: 7440.8844 | D15: 7506.5004 | E15: 7842.7035 | F15: 7988.7424 | G15: 8008.7287 | H15: 7949.6397 | L15: =B15/(B15+B35+B55) -> 0.23705319 | M15: =C15/(C15+C35+C55) -> 0.22018359 | N15: =D15/(D15+D35+D55) -> 0.21425718 | O15: =E15/(E15+E35+E55) -> 0.21365689 | P15: =F15/(F15+F35+F55) -> 0.21085152 | Q15: =G15/(G15+G35+G55) -> 0.20628825 | R15: =H15/(H15+H35+H55) -> 0.19995069
A16: Perry | B16: 8087.6459 | C16: 8338.7692 | D16: 8345.9653 | E16: 8414.6172 | F16: 8520.4135 | G16: 8594.5163 | H16: 8700.4312 | L16: =B16/(B16+B36+B56) -> 0.24673254 | M16: =C16/(C16+C36+C56) -> 0.24360997 | N16: =D16/(D16+D36+D56) -> 0.23992311 | O16: =E16/(E16+E36+E56) -> 0.23701812 | P16: =F16/(F16+F36+F56) -> 0.2364614 | Q16: =G16/(G16+G36+G56) -> 0.23564051 | R16: =H16/(H16+H36+H56) -> 0.23570101
... A19: Union | B19: 15030.25 | C19: 16039.348 | D19: 17946.235 | E19: 19936.6 | F19: 21575.9 | G19: 22584.109 | H19: 23471.02 | L19: =B19/(B19+B39+B59) -> 0.25002912 | M19: =C19/(C19+C39+C59) -> 0.25165683 | N19: =D19/(D19+D39+D59) -> 0.25700997 | O19: =E19/(E19+E39+E59) -> 0.26146703 | P19: =F19/(F19+F39+F59) -> 0.26217753 | Q19: =G19/(G19+G39+G59) -> 0.25619217 | R19: =H19/(H19+H39+H59) -> 0.24965983
A20: Total | B20: =SUM(B5:B19) -> 560681.45 | C20: =SUM(C5:C19) -> 586442.06 | D20: =SUM(D5:D19) -> 608792.74 | E20: =SUM(E5:E19) -> 636512.95 | F20: =SUM(F5:F19) -> 660611.89 | G20: =SUM(G5:G19) -> 678549.34 | H20: =SUM(H5:H19) -> 698262.24 | L20: =B20/(B20+B40+B60) -> 0.23571712 | M20: =C20/(C20+C40+C60) -> 0.2332066 | N20: =D20/(D20+D40+D60) -> 0.2309309 | O20: =E20/(E20+E40+E60) -> 0.22843101 | P20: =F20/(F20+F40+F60) -> 0.22748915 | Q20: =G20/(G20+G40+G60) -> 0.22580406 | R20: =H20/(H20+H40+H60) -> 0.22480027
A22: Household Population by Age 18 - 64
B23: Estimate | C23: Projections | K23: Share of Total Household Population
A24: COUNTY | B24: 2020 | C24: 2025 | D24: 2030 | E24: 2035 | F24: 2040 | G24: 2045 | H24: 2050 | L24: 2020 | M24: 2025 | N24: 2030 | O24: 2035 | P24: 2040 | Q24: 2045 | R24: 2050
A25: Delaware | B25: 126668.53 | C25: 145319.24 | D25: 160653.84 | E25: 177640.12 | F25: 192780.78 | G25: 208387.53 | H25: 224128.5 | L25: =B25/(B5+B25+B45) -> 0.59942421 | M25: =C25/(C5+C25+C45) -> 0.59509508 | N25: =D25/(D5+D25+D45) -> 0.58494665 | O25: =E25/(E5+E25+E45) -> 0.57674054 | P25: =F25/(F5+F25+F45) -> 0.57028985 | Q25: =G25/(G5+G25+G45) -> 0.56872619 | R25: =H25/(H5+H25+H45) -> 0.56772438
A26: Fairfield | B26: 93009.151 | C26: 97008.336 | D26: 100239.14 | E26: 105773.38 | F26: 111882.19 | G26: 118235.31 | H26: 124206.67 | L26: =B26/(B6+B26+B46) -> 0.5953805 | M26: =C26/(C6+C26+C46) -> 0.58272014 | N26: =D26/(D6+D26+D46) -> 0.57039617 | O26: =E26/(E6+E26+E46) -> 0.56836545 | P26: =F26/(F6+F26+F46) -> 0.57315226 | Q26: =G26/(G6+G26+G46) -> 0.58050397 | R26: =H26/(H6+H26+H46) -> 0.58546904
A27: Fayette | B27: 14679.628 | C27: 14695.061 | D27: 14967.915 | E27: 15299.343 | F27: 15600.579 | G27: 15984.655 | H27: 16395.187 | L27: =B27/(B7+B27+B47) -> 0.55769424 | M27: =C27/(C7+C27+C47) -> 0.54852784 | N27: =D27/(D7+D27+D47) -> 0.54663337 | O27: =E27/(E7+E27+E47) -> 0.54630756 | P27: =F27/(F7+F27+F47) -> 0.54564649 | Q27: =G27/(G7+G27+G47) -> 0.54815182 | R27: =H27/(H7+H27+H47) -> 0.55145091
A28: Franklin | B28: 843951.03 | C28: 868734.1 | D28: 894781.84 | E28: 942968.28 | F28: 982849.44 | G28: 1019973.1 | H28: 1048743.2 | L28: =B28/(B8+B28+B48) -> 0.63897394 | M28: =C28/(C8+C28+C48) -> 0.62629883 | N28: =D28/(D8+D28+D48) -> 0.61963742 | O28: =E28/(E8+E28+E48) -> 0.62169087 | P28: =F28/(F8+F28+F48) -> 0.62543236 | Q28: =G28/(G8+G28+G48) -> 0.63072458 | R28: =H28/(H8+H28+H48) -> 0.6307035
A29: Hocking | B29: 14145.807 | C29: 13599.748 | D29: 12986.347 | E29: 12769.056 | F29: 12631.528 | G29: 12670.692 | H29: 12736.21 | L29: =B29/(B9+B29+B49) -> 0.55646147 | M29: =C29/(C9+C29+C49) -> 0.53677564 | N29: =D29/(D9+D29+D49) -> 0.516705 | O29: =E29/(E9+E29+E49) -> 0.51076224 | P29: =F29/(F9+F29+F49) -> 0.50935634 | Q29: =G29/(G9+G29+G49) -> 0.51588664 | R29: =H29/(H9+H29+H49) -> 0.52360672
A30: Knox | B30: 33642.314 | C30: 33084.544 | D30: 32947.024 | E30: 33588.691 | F30: 34494.499 | G30: 35497.844 | H30: 36398.449 | L30: =B30/(B10+B30+B50) -> 0.5605651 | M30: =C30/(C10+C30+C50) -> 0.53840656 | N30: =D30/(D10+D30+D50) -> 0.52606658 | O30: =E30/(E10+E30+E50) -> 0.52237467 | P30: =F30/(F10+F30+F50) -> 0.52735819 | Q30: =G30/(G10+G30+G50) -> 0.53588931 | R30: =H30/(H10+H30+H50) -> 0.54267726
A31: Licking | B31: 104397.21 | C31: 108968.46 | D31: 112430.62 | E31: 121499.29 | F31: 127971.11 | G31: 133449.07 | H31: 137874.64 | L31: =B31/(B11+B31+B51) -> 0.59356055 | M31: =C31/(C11+C31+C51) -> 0.57876365 | N31: =D31/(D11+D31+D51) -> 0.56762216 | O31: =E31/(E11+E31+E51) -> 0.56689542 | P31: =F31/(F11+F31+F51) -> 0.5733601 | Q31: =G31/(G11+G31+G51) -> 0.58433163 | R31: =H31/(H11+H31+H51) -> 0.59030774
A32: Logan | B32: 24644.238 | C32: 23854.492 | D32: 23461.02 | E32: 23521.099 | F32: 23777.729 | G32: 24226.515 | H32: 24757.648 | L32: =B32/(B12+B32+B52) -> 0.56709479 | M32: =C32/(C12+C32+C52) -> 0.54960468 | N32: =D32/(D12+D32+D52) -> 0.53666897 | O32: =E32/(E12+E32+E52) -> 0.53369712 | P32: =F32/(F12+F32+F52) -> 0.53593276 | Q32: =G32/(G12+G32+G52) -> 0.54266005 | R32: =H32/(H12+H32+H52) -> 0.5511375
A33: Madison | B33: 25500.531 | C33: 26622.86 | D33: 27479.179 | E33: 28752.469 | F33: 30257.325 | G33: 31774.778 | H33: 33212.834 | L33: =B33/(B13+B33+B53) -> 0.61902006 | M33: =C33/(C13+C33+C53) -> 0.60702404 | N33: =D33/(D13+D33+D53) -> 0.59473593 | O33: =E33/(E13+E33+E53) -> 0.58939526 | P33: =F33/(F13+F33+F53) -> 0.59215463 | Q33: =G33/(G13+G33+G53) -> 0.59641824 | R33: =H33/(H13+H33+H53) -> 0.59891504
A34: Marion | B34: 37112.487 | C34: 35839.639 | D34: 35177.507 | E34: 35756.962 | F34: 36420.845 | G34: 36727.521 | H34: 36724.715 | L34: =B34/(B14+B34+B54) -> 0.59204733 | M34: =C34/(C14+C34+C54) -> 0.5721526 | N34: =D34/(D14+D34+D54) -> 0.56296622 | O34: =E34/(E14+E34+E54) -> 0.57143481 | P34: =F34/(F14+F34+F54) -> 0.58377966 | Q34: =G34/(G14+G34+G54) -> 0.59179713 | R34: =H34/(H14+H34+H54) -> 0.59489601
A35: Morrow | B35: 18507.093 | C35: 18897.973 | D35: 19081.609 | E35: 19633.623 | F35: 20177.664 | G35: 20844.328 | H35: 21657.811 | L35: =B35/(B15+B35+B55) -> 0.57263816 | M35: =C35/(C15+C35+C55) -> 0.5592109 | N35: =D35/(D15+D35+D55) -> 0.54464418 | O35: =E35/(E15+E35+E55) -> 0.53487409 | P35: =F35/(F15+F35+F55) -> 0.53256082 | Q35: =G35/(G15+G35+G55) -> 0.53690669 | R35: =H35/(H15+H35+H55) -> 0.54474095
A36: Perry | B36: 18796.122 | C36: 18876.442 | D36: 18704.192 | E36: 18867.554 | F36: 19252.468 | G36: 19693.725 | H36: 20069.936 | L36: =B36/(B16+B36+B56) -> 0.57341964 | M36: =C36/(C16+C36+C56) -> 0.55145902 | N36: =D36/(D16+D36+D56) -> 0.53769311 | O36: =E36/(E16+E36+E56) -> 0.53145044 | P36: =F36/(F16+F36+F56) -> 0.53430101 | Q36: =G36/(G16+G36+G56) -> 0.53995352 | R36: =H36/(H16+H36+H56) -> 0.54370915
... A39: Union | B39: 37138.806 | C39: 38390.007 | D39: 40842.57 | E39: 44016.47 | F39: 47677.588 | G39: 51941.969 | H39: 56178.464 | L39: =B39/(B19+B39+B59) -> 0.61780626 | M39: =C39/(C19+C39+C59) -> 0.60233791 | N39: =D39/(D19+D39+D59) -> 0.58491085 | O39: =E39/(E19+E39+E59) -> 0.57727275 | P39: =F39/(F19+F39+F59) -> 0.57934975 | Q39: =G39/(G19+G39+G59) -> 0.5892252 | R39: =H39/(H19+H39+H59) -> 0.59756695
A40: Total | B40: =SUM(B25:B39) -> 1471405.5 | C40: =SUM(C25:C39) -> 1523402.3 | D40: =SUM(D25:D39) -> 1574059 | E40: =SUM(E25:E39) -> 1662136.5 | F40: =SUM(F25:F39) -> 1740368.9 | G40: =SUM(G25:G39) -> 1816086.3 | H40: =SUM(H25:H39) -> 1881964.4 | L40: =B40/(B20+B40+B60) -> 0.61859627 | M40: =C40/(C20+C40+C60) -> 0.60580148 | N40: =D40/(D20+D40+D60) -> 0.59708147 | O40: =E40/(E20+E40+E60) -> 0.59650555 | P40: =F40/(F20+F40+F60) -> 0.59931565 | Q40: =G40/(G20+G40+G60) -> 0.6043476 | R40: =H40/(H20+H40+H60) -> 0.60588426
A42: Household Population by Age 65 and older
B43: Estimate | C43: Projections | L43: Share of Total Household Population
A44: COUNTY | B44: 2020 | C44: 2025 | D44: 2030 | E44: 2035 | F44: 2040 | G44: 2045 | H44: 2050 | L44: 2020 | M44: 2025 | N44: 2030 | O44: 2035 | P44: 2040 | Q44: 2045 | R44: 2050
A45: Delaware | B45: 31188.89 | C45: 41073.544 | D45: 51504.759 | E45: 61937.721 | F45: 70674.245 | G45: 77730.785 | H45: 85039.985 | L45: =B45/(B45+B25+B5) -> 0.14759291 | M45: =C45/(C45+C25+C5) -> 0.16819978 | N45: =D45/(D45+D25+D5) -> 0.18753076 | O45: =E45/(E45+E25+E5) -> 0.20109193 | P45: =F45/(F45+F25+F5) -> 0.20907066 | Q45: =G45/(G45+G25+G5) -> 0.21214097 | R45: =H45/(H45+H25+H5) -> 0.21540889
A46: Fairfield | B46: 25870.113 | C46: 29597.686 | D46: 33063.753 | E46: 35035.338 | F46: 35695.856 | G46: 35758.851 | H46: 36262.595 | L46: =B46/(B46+B26+B6) -> 0.16560264 | M46: =C46/(C46+C26+C6) -> 0.17779058 | N46: =D46/(D46+D26+D6) -> 0.18814445 | O46: =E46/(E46+E26+E6) -> 0.1882598 | P46: =F46/(F46+F26+F6) -> 0.18286343 | Q46: =G46/(G46+G26+G6) -> 0.17556647 | R46: =H46/(H46+H26+H6) -> 0.17092984
...

Sheet Households and Housing Units
C1: County Growth Projections Households and Housing Units
A2: Households
B3: Estimate | C3: Projections | L3: Average Household Size (1)
A4: COUNTY | B4: 2020 | C4: 2025 | D4: 2030 | E4: 2035 | F4: 2040 | G4: 2045 | H4: 2050 | L4: 2020 | M4: 2025 | N4: 2030 | O4: 2035 | P4: 2040 | Q4: 2045 | R4: 2050
A5: Delaware | B5: 74757.394 | C5: 85864.789 | D5: 96455.986 | E5: 108058.8 | F5: 118505.63 | G5: 128374.3 | H5: 138242.96 | L5: ='Group Quarters and Households'!B25/'Households and Housing Units'!B5 -> 2.8267037 | M5: ='Group Quarters and Households'!C25/'Households and Housing Units'!C5 -> 2.8388703 | N5: ='Group Quarters and Households'!D25/'Households and Housing Units'!D5 -> 2.8389011 | O5: ='Group Quarters and Households'!E25/'Households and Housing Units'!E5 -> 2.8389913 | P5: ='Group Quarters and Households'!F25/'Households and Housing Units'!F5 -> 2.8391055 | Q5: ='Group Quarters and Households'!G25/'Households and Housing Units'!G5 -> 2.8391198 | R5: ='Group Quarters and Households'!H25/'Households and Housing Units'!H5 -> 2.839103
A6: Fairfield | B6: 58303.358 | C6: 61898.507 | D6: 65288.806 | E6: 69083.209 | F6: 72415.299 | G6: 75516.418 | H6: 78617.537 | L6: ='Group Quarters and Households'!B26/'Households and Housing Units'!B6 -> 2.6720073 | M6: ='Group Quarters and Households'!C26/'Households and Housing Units'!C6 -> 2.678966 | N6: ='Group Quarters and Households'!D26/'Households and Housing Units'!D6 -> 2.678744 | O6: ='Group Quarters and Households'!E26/'Households and Housing Units'!E6 -> 2.6788565 | P6: ='Group Quarters and Households'!F26/'Households and Housing Units'!F6 -> 2.6790886 | Q6: ='Group Quarters and Households'!G26/'Households and Housing Units'!G6 -> 2.6793247 | R6: ='Group Quarters and Households'!H26/'Households and Housing Units'!H6 -> 2.6794658
A7: Fayette | B7: 11875.104 | C7: 12071.784 | D7: 12314.938 | E7: 12570.539 | F7: 12811.203 | G7: 13044.813 | H7: 13278.838 | L7: ='Group Quarters and Households'!B27/'Households and Housing Units'!B7 -> 2.4098316 | M7: ='Group Quarters and Households'!C27/'Households and Housing Units'!C7 -> 2.4075149 | N7: ='Group Quarters and Households'!D27/'Households and Housing Units'!D7 -> 2.4061023 | O7: ='Group Quarters and Households'!E27/'Households and Housing Units'!E7 -> 2.4059429 | P7: ='Group Quarters and Households'!F27/'Households and Housing Units'!F7 -> 2.4062533 | Q7: ='Group Quarters and Households'!G27/'Households and Housing Units'!G7 -> 2.406857 | R7: ='Group Quarters and Households'!H27/'Households and Housing Units'!H7 -> 2.4074395
A8: Franklin | B8: 526242.28 | C8: 552519.92 | D8: 575160.57 | E8: 604077.24 | F8: 625821.14 | G8: 643977.64 | H8: 662134.15 | L8: ='Group Quarters and Households'!B28/'Households and Housing Units'!B8 -> 2.4593444 | M8: ='Group Quarters and Households'!C28/'Households and Housing Units'!C8 -> 2.4598172 | N8: ='Group Quarters and Households'!D28/'Households and Housing Units'!D8 -> 2.4597844 | O8: ='Group Quarters and Households'!E28/'Households and Housing Units'!E8 -> 2.4595779 | P8: ='Group Quarters and Households'!F28/'Households and Housing Units'!F8 -> 2.4594967 | Q8: ='Group Quarters and Households'!G28/'Households and Housing Units'!G8 -> 2.4593167 | R8: ='Group Quarters and Households'!H28/'Households and Housing Units'!H8 -> 2.459269
A9: Hocking | B9: 11423.237 | C9: 11409.544 | D9: 11326.556 | E9: 11272.199 | F9: 11190.456 | G9: 11093.361 | H9: 10996.68 | L9: ='Group Quarters and Households'!B29/'Households and Housing Units'!B9 -> 2.4137643 | M9: ='Group Quarters and Households'!C29/'Households and Housing Units'!C9 -> 2.4080718 | N9: ='Group Quarters and Households'!D29/'Households and Housing Units'!D9 -> 2.4072631 | O9: ='Group Quarters and Households'!E29/'Households and Housing Units'!E9 -> 2.406895 | P9: ='Group Quarters and Households'!F29/'Households and Housing Units'!F9 -> 2.406783 | Q9: ='Group Quarters and Households'!G29/'Households and Housing Units'!G9 -> 2.4069351 | R9: ='Group Quarters and Households'!H29/'Households and Housing Units'!H9 -> 2.4072719
A10: Knox | B10: 23410.317 | C10: 23929.365 | D10: 24370.238 | E10: 24994.841 | F10: 25409.524 | G10: 25719.841 | H10: 26030.556 | L10: ='Group Quarters and Households'!B30/'Households and Housing Units'!B10 -> 2.520897 | M10: ='Group Quarters and Households'!C30/'Households and Housing Units'!C10 -> 2.5253073 | N10: ='Group Quarters and Households'!D30/'Households and Housing Units'!D10 -> 2.5267295 | O10: ='Group Quarters and Households'!E30/'Households and Housing Units'!E10 -> 2.5274815 | P10: ='Group Quarters and Households'!F30/'Households and Housing Units'!F10 -> 2.5271627 | Q10: ='Group Quarters and Households'!G30/'Households and Housing Units'!G10 -> 2.5263375 | R10: ='Group Quarters and Households'!H30/'Households and Housing Units'!H10 -> 2.5256472
A11: Licking | B11: 65657.519 | C11: 70153.383 | D11: 73752.632 | E11: 79724.436 | F11: 82984.211 | G11: 84889.098 | H11: 86794.361 | L11: ='Group Quarters and Households'!B31/'Households and Housing Units'!B11 -> 2.6572128 | M11: ='Group Quarters and Households'!C31/'Households and Housing Units'!C11 -> 2.6598147 | N11: ='Group Quarters and Households'!D31/'Households and Housing Units'!D11 -> 2.6599593 | O11: ='Group Quarters and Households'!E31/'Households and Housing Units'!E11 -> 2.6599498 | P11: ='Group Quarters and Households'!F31/'Households and Housing Units'!F11 -> 2.6598433 | Q11: ='Group Quarters and Households'!G31/'Households and Housing Units'!G11 -> 2.659517 | R11: ='Group Quarters and Households'!H31/'Households and Housing Units'!H11 -> 2.6592972
A12: Logan | B12: 18911.203 | C12: 18923.651 | D12: 19051.452 | E12: 19197.925 | F12: 19318.672 | G12: 19432.365 | H12: 19546.058 | L12: ='Group Quarters and Households'!B32/'Households and Housing Units'!B12 -> 2.4137015 | M12: ='Group Quarters and Households'!C32/'Households and Housing Units'!C12 -> 2.407622 | N12: ='Group Quarters and Households'!D32/'Households and Housing Units'!D12 -> 2.4064307 | O12: ='Group Quarters and Households'!E32/'Households and Housing Units'!E12 -> 2.4060933 | P12: ='Group Quarters and Households'!F32/'Households and Housing Units'!F12 -> 2.4061695 | Q12: ='Group Quarters and Households'!G32/'Households and Housing Units'!G12 -> 2.4063978 | R12: ='Group Quarters and Households'!H32/'Households and Housing Units'!H12 -> 2.4067257
A13: Madison | B13: 14843.846 | C13: 15746.154 | D13: 16540.769 | E13: 17414.231 | F13: 18198.077 | G13: 18936.154 | H13: 19674.231 | L13: ='Group Quarters and Households'!B33/'Households and Housing Units'!B13 -> 2.60128 | M13: ='Group Quarters and Households'!C33/'Households and Housing Units'!C13 -> 2.6048901 | N13: ='Group Quarters and Households'!D33/'Households and Housing Units'!D13 -> 2.6087662 | O13: ='Group Quarters and Households'!E33/'Households and Housing Units'!E13 -> 2.6105661 | P13: ='Group Quarters and Households'!F33/'Households and Housing Units'!F13 -> 2.6090669 | Q13: ='Group Quarters and Households'!G33/'Households and Housing Units'!G13 -> 2.6076573 | R13: ='Group Quarters and Households'!H33/'Households and Housing Units'!H13 -> 2.6069634
