Workbook

Sheet Figures

Sheet Population Chart Data
A1: County | B1: Variable | C1: 1980 | D1: 1990 | E1: 2000 | F1: 2010 | G1: 2020 | H1: 2021 | I1: 2025 | J1: 2030 | K1: 2035 | L1: 2040 | M1: 2045 | N1: 2050 | O1: 1980 label | P1: 2020 label | Q1: 2050 label
A2: Delaware | B2: Historic population | C2: ='Total Population'!B5 -> 53840 | D2: ='Total Population'!C5 -> 67482 | E2: ='Total Population'!D5 -> 111759 | F2: ='Total Population'!E5 -> 175099 | G2: ='Total Population'!F5 -> 215062 | H2: ='Total Population'!G5 -> 220740
A3: Delaware | B3: Forecasted population | I3: ='Total Population'!H5 -> 247016 | J3: ='Total Population'!M5 -> 277484 | K3: ='Total Population'!R5 -> 310863 | L3: ='Total Population'!W5 -> 340917 | M3: ='Total Population'!AB5 -> 369307 | N3: ='Total Population'!AG5 -> 397697
A4: Delaware | B4: Confidence limit | I4: ='Total Population'!I5 -> 248441 | J4: ='Total Population'!N5 -> 287218 | K4: ='Total Population'!S5 -> 329249 | L4: ='Total Population'!X5 -> 373888 | M4: ='Total Population'!AC5 -> 420768 | N4: ='Total Population'!AH5 -> 469644
A5: Delaware | B5: Confidence limit | I5: ='Total Population'!J5 -> 238464 | J5: ='Total Population'!O5 -> 256467 | K5: ='Total Population'!T5 -> 271216 | L5: ='Total Population'!Y5 -> 283357 | M5: ='Total Population'!AD5 -> 293257 | N5: ='Total Population'!AI5 -> 301161
A6: Fairfield | B6: Historic population | C6: ='Total Population'!B6 -> 93678 | D6: ='Total Population'!C6 -> 103823 | E6: ='Total Population'!D6 -> 123485 | F6: ='Total Population'!E6 -> 146417 | G6: ='Total Population'!F6 -> 159357 | H6: ='Total Population'!G6 -> 161064
A7: Fairfield | B7: Forecasted population | I7: ='Total Population'!H6 -> 169183 | J7: ='Total Population'!M6 -> 178449 | K7: ='Total Population'!R6 -> 188820 | L7: ='Total Population'!W6 -> 197928 | M7: ='Total Population'!AB6 -> 206404 | N7: ='Total Population'!AG6 -> 214880
A8: Fairfield | B8: Confidence limit | I8: ='Total Population'!I6 -> 171704 | J8: ='Total Population'!N6 -> 188541 | K8: ='Total Population'!S6 -> 208055 | L8: ='Total Population'!X6 -> 229705 | M8: ='Total Population'!AC6 -> 253189 | N8: ='Total Population'!AH6 -> 278304
A9: Fairfield | B9: Confidence limit | I9: ='Total Population'!J6 -> 163990 | J9: ='Total Population'!O6 -> 164104 | K9: ='Total Population'!T6 -> 161542 | L9: ='Total Population'!Y6 -> 156843 | M9: ='Total Population'!AD6 -> 150311 | N9: ='Total Population'!AI6 -> 142147
A10: Fayette | B10: Historic population | C10: ='Total Population'!B7 -> 27467 | D10: ='Total Population'!C7 -> 27501 | E10: ='Total Population'!D7 -> 28495 | F10: ='Total Population'!E7 -> 29014 | G10: ='Total Population'!F7 -> 28939 | H10: ='Total Population'!G7 -> 28906
A11: Fayette | B11: Forecasted population | I11: ='Total Population'!H7 -> 29419 | J11: ='Total Population'!M7 -> 30011 | K11: ='Total Population'!R7 -> 30634 | L11: ='Total Population'!W7 -> 31220 | M11: ='Total Population'!AB7 -> 31790 | N11: ='Total Population'!AG7 -> 32360
A12: Fayette | B12: Confidence limit | I12: ='Total Population'!I7 -> 29855 | J12: ='Total Population'!N7 -> 31216 | K12: ='Total Population'!S7 -> 32814 | L12: ='Total Population'!X7 -> 34594 | M12: ='Total Population'!AC7 -> 36534 | N12: ='Total Population'!AH7 -> 38618
A13: Fayette | B13: Confidence limit | I13: ='Total Population'!J7 -> 28912 | J13: ='Total Population'!O7 -> 28691 | K13: ='Total Population'!T7 -> 28240 | L13: ='Total Population'!Y7 -> 27601 | M13: ='Total Population'!AD7 -> 26802 | N13: ='Total Population'!AI7 -> 25859
A14: Franklin | B14: Historic population | C14: ='Total Population'!B8 -> 869126 | D14: ='Total Population'!C8 -> 965600 | E14: ='Total Population'!D8 -> 1072018 | F14: ='Total Population'!E8 -> 1166202 | G14: ='Total Population'!F8 -> 1324013 | H14: ='Total Population'!G8 -> 1321414
A15: Franklin | B15: Forecasted population | I15: ='Total Population'!H8 -> 1390127 | J15: ='Total Population'!M8 -> 1447090 | K15: ='Total Population'!R8 -> 1519844 | L15: ='Total Population'!W8 -> 1574551 | M15: ='Total Population'!AB8 -> 1620232 | N15: ='Total Population'!AG8 -> 1665914
A16: Franklin | B16: Confidence limit | I16: ='Total Population'!I8 -> 1409654 | J16: ='Total Population'!N8 -> 1506988 | K16: ='Total Population'!S8 -> 1617180 | L16: ='Total Population'!X8 -> 1738045 | M16: ='Total Population'!AC8 -> 1868239 | N16: ='Total Population'!AH8 -> 2006828
A17: Franklin | B17: Confidence limit | I17: ='Total Population'!J8 -> 1333445 | J17: ='Total Population'!O8 -> 1327469 | K17: ='Total Population'!T8 -> 1308636 | L17: ='Total Population'!Y8 -> 1279131 | M17: ='Total Population'!AD8 -> 1240296 | N17: ='Total Population'!AI8 -> 1193066
A18: Hocking | B18: Historic population | C18: ='Total Population'!B9 -> 24304 | D18: ='Total Population'!C9 -> 25594 | E18: ='Total Population'!D9 -> 28262 | F18: ='Total Population'!E9 -> 29478 | G18: ='Total Population'!F9 -> 27999 | H18: ='Total Population'!G9 -> 28097
A19: Hocking | B19: Forecasted population | I19: ='Total Population'!H9 -> 27965 | J19: ='Total Population'!M9 -> 27762 | K19: ='Total Population'!R9 -> 27629 | L19: ='Total Population'!W9 -> 27428 | M19: ='Total Population'!AB9 -> 27190 | N19: ='Total Population'!AG9 -> 26953
A20: Hocking | B20: Confidence limit | I20: ='Total Population'!I9 -> 28660 | J20: ='Total Population'!N9 -> 29751 | K20: ='Total Population'!S9 -> 31239 | L20: ='Total Population'!X9 -> 33041 | M20: ='Total Population'!AC9 -> 35114 | N20: ='Total Population'!AH9 -> 37429
A21: Hocking | B21: Confidence limit | I21: ='Total Population'!J9 -> 27122 | J21: ='Total Population'!O9 -> 25535 | K21: ='Total Population'!T9 -> 23571 | L21: ='Total Population'!Y9 -> 21295 | M21: ='Total Population'!AD9 -> 18747 | N21: ='Total Population'!AI9 -> 15958
A22: Knox | B22: Historic population | C22: ='Total Population'!B10 -> 46304 | D22: ='Total Population'!C10 -> 47637 | E22: ='Total Population'!D10 -> 54616 | F22: ='Total Population'!E10 -> 61090 | G22: ='Total Population'!F10 -> 62765 | H22: ='Total Population'!G10 -> 62897
A23: Knox | B23: Forecasted population | I23: ='Total Population'!H10 -> 64157 | J23: ='Total Population'!M10 -> 65339 | K23: ='Total Population'!R10 -> 67013 | L23: ='Total Population'!W10 -> 68125 | M23: ='Total Population'!AB10 -> 68957 | N23: ='Total Population'!AG10 -> 69790
A24: Knox | B24: Confidence limit | I24: ='Total Population'!I10 -> 65164 | J24: ='Total Population'!N10 -> 69227 | K24: ='Total Population'!S10 -> 74288 | L24: ='Total Population'!X10 -> 80150 | M24: ='Total Population'!AC10 -> 86702 | N24: ='Total Population'!AH10 -> 93868
A25: Knox | B25: Confidence limit | I25: ='Total Population'!J10 -> 61970 | J25: ='Total Population'!O10 -> 59572 | K25: ='Total Population'!T10 -> 56176 | L25: ='Total Population'!Y10 -> 51978 | M25: ='Total Population'!AD10 -> 47091 | N25: ='Total Population'!AI10 -> 41589
A26: Licking | B26: Historic population | C26: ='Total Population'!B11 -> 120981 | D26: ='Total Population'!C11 -> 129006 | E26: ='Total Population'!D11 -> 146268 | F26: ='Total Population'!E11 -> 166705 | G26: ='Total Population'!F11 -> 178680 | H26: ='Total Population'!G11 -> 180401
A27: Licking | B27: Forecasted population | I27: ='Total Population'!H11 -> 190915 | J27: ='Total Population'!M11 -> 200710 | K27: ='Total Population'!R11 -> 216962 | L27: ='Total Population'!W11 -> 225833 | M27: ='Total Population'!AB11 -> 231017 | N27: ='Total Population'!AG11 -> 236202
A28: Licking | B28: Confidence limit | I28: ='Total Population'!I11 -> 189312 | J28: ='Total Population'!N11 -> 203164 | K28: ='Total Population'!S11 -> 219200 | L28: ='Total Population'!X11 -> 237045 | M28: ='Total Population'!AC11 -> 256471 | N28: ='Total Population'!AH11 -> 277319
A29: Licking | B29: Confidence limit | I29: ='Total Population'!J11 -> 176808 | J29: ='Total Population'!O11 -> 173324 | K29: ='Total Population'!T11 -> 167658 | L29: ='Total Population'!Y11 -> 160181 | M29: ='Total Population'!AD11 -> 151123 | N29: ='Total Population'!AI11 -> 140644
A30: Logan | B30: Historic population | C30: ='Total Population'!B12 -> 39155 | D30: ='Total Population'!C12 -> 42417 | E30: ='Total Population'!D12 -> 45984 | F30: ='Total Population'!E12 -> 45743 | G30: ='Total Population'!F12 -> 46065 | H30: ='Total Population'!G12 -> 46035
A31: Logan | B31: Forecasted population | I31: ='Total Population'!H12 -> 46095 | J31: ='Total Population'!M12 -> 46407 | K31: ='Total Population'!R12 -> 46763 | L31: ='Total Population'!W12 -> 47058 | M31: ='Total Population'!AB12 -> 47335 | N31: ='Total Population'!AG12 -> 47611
A32: Logan | B32: Confidence limit | I32: ='Total Population'!I12 -> 47290 | J32: ='Total Population'!N12 -> 49351 | K32: ='Total Population'!S12 -> 51833 | L32: ='Total Population'!X12 -> 54679 | M32: ='Total Population'!AC12 -> 57844 | N32: ='Total Population'!AH12 -> 61297
A33: Logan | B33: Confidence limit | I33: ='Total Population'!J12 -> 44871 | J33: ='Total Population'!O12 -> 43377 | K33: ='Total Population'!T12 -> 41448 | L33: ='Total Population'!Y12 -> 39156 | M33: ='Total Population'!AD12 -> 36544 | N33: ='Total Population'!AI12 -> 33644
A34: Madison | B34: Historic population | C34: ='Total Population'!B13 -> 33004 | D34: ='Total Population'!C13 -> 37111 | E34: ='Total Population'!D13 -> 40218 | F34: ='Total Population'!E13 -> 43434 | G34: ='Total Population'!F13 -> 43823 | H34: ='Total Population'!G13 -> 44386
A35: Madison | B35: Forecasted population | I35: ='Total Population'!H13 -> 46487 | J35: ='Total Population'!M13 -> 48833 | K35: ='Total Population'!R13 -> 51412 | L35: ='Total Population'!W13 -> 53726 | M35: ='Total Population'!AB13 -> 55905 | N35: ='Total Population'!AG13 -> 58084
A36: Madison | B36: Confidence limit | I36: ='Total Population'!I13 -> 49508 | J36: ='Total Population'!N13 -> 58168 | K36: ='Total Population'!S13 -> 68798 | L36: ='Total Population'!X13 -> 81014 | M36: ='Total Population'!AC13 -> 94597 | N36: ='Total Population'!AH13 -> 109400
A37: Madison | B37: Confidence limit | I37: ='Total Population'!J13 -> 42918 | J37: ='Total Population'!O13 -> 38616 | K37: ='Total Population'!T13 -> 32345 | L37: ='Total Population'!Y13 -> 24486 | M37: ='Total Population'!AD13 -> 15261 | N37: ='Total Population'!AI13 -> 4816
A38: Marion | B38: Historic population | C38: ='Total Population'!B14 -> 67974 | D38: ='Total Population'!C14 -> 64289 | E38: ='Total Population'!D14 -> 66135 | F38: ='Total Population'!E14 -> 66458 | G38: ='Total Population'!F14 -> 65363 | H38: ='Total Population'!G14 -> 65291
A39: Marion | B39: Forecasted population | I39: ='Total Population'!H14 -> 65314 | J39: ='Total Population'!M14 -> 65160 | K39: ='Total Population'!R14 -> 65246 | L39: ='Total Population'!W14 -> 65059 | M39: ='Total Population'!AB14 -> 64732 | N39: ='Total Population'!AG14 -> 64405
A40: Marion | B40: Confidence limit | I40: ='Total Population'!I14 -> 66329 | J40: ='Total Population'!N14 -> 66651 | K40: ='Total Population'!S14 -> 66806 | L40: ='Total Population'!X14 -> 66879 | M40: ='Total Population'!AC14 -> 66903 | N40: ='Total Population'!AH14 -> 66892
...

Sheet Other chart data
B1: Population | C1: Households | D1: Labor force | E1: Population (round) | F1: Households (round) | G1: Labor force (round) | H1: Population (label) | I1: Households (label) | J1: Labor force (label)
A2: 2020 Total | B2: ='Total Population'!F20 -> 2421159 | C2: ='Households and Housing Units'!B20 -> 927777.8 | D2: ='Residential Labor Force'!B20 -> 1262535.5 | E2: =ROUND(B2,-3) -> 2421000 | F2: =ROUND(C2,-3) -> 928000 | G2: =ROUND(D2,-3) -> 1263000 | H2: =_xlfn.CONCAT(TEXT(E2,"_(* #,##0_)"), "in 2020") -> 2,421,000 in 2020 | I2: =_xlfn.CONCAT(TEXT(F2,"_(* #,##0_)"), "in 2020") -> 928,000 in 2020 | J2: =_xlfn.CONCAT(TEXT(G2,"_(* #,##0_)"), "in 2020") -> 1,263,000 in 2020
A3: 2050 Total | B3: ='Total Population'!AG20 -> 3147011 | C3: ='Households and Housing Units'!H20 -> 1199937.5 | D3: ='Residential Labor Force'!H20 -> 1619518.8 | E3: =ROUND(B3,-3) -> 3147000 | F3: =ROUND(C3,-3) -> 1200000 | G3: =ROUND(D3,-3) -> 1620000
A4: Change 2020-2050 | B4: =B3-B2 -> 725852 | C4: =C3-C2 -> 272159.67 | D4: =D3-D2 -> 356983.29 | E4: =ROUND(B4,-3) -> 726000 | F4: =F3-F2 -> 272000 | G4: =G3-G2 -> 357000 | H4: =_xlfn.CONCAT(TEXT(E4, "+_(* #,##0_);-_(* #,##0_);_(* #,##0_)"), "(",TEXT(E5,"0%"), ")", " by 2050") -> + 726,000 (30%) by 2050 | I4: =_xlfn.CONCAT(TEXT(F4, "+_(* #,##0_);-_(* #,##0_);_(* #,##0_)"), "(",TEXT(F5,"0%"), ")", " by 2050") -> + 272,000 (29%) by 2050 | J4: =_xlfn.CONCAT(TEXT(G4, "+_(* #,##0_);-_(* #,##0_);_(* #,##0_)"), "(",TEXT(G5,"0%"), ")", " by 2050") -> + 357,000 (28%) by 2050
A5: Percent change | B5: =B4/B2 -> 0.29979526 | C5: =C4/C2 -> 0.29334575 | D5: =D4/D2 -> 0.2827511 | E5: =E4/E2 -> 0.29987608 | F5: =F4/F2 -> 0.29310345 | G5: =G4/G2 -> 0.28266033

Sheet Total Population
D1: County Growth Projections Total Population
A2: Total Population | AM2: Historic Growth Overview | AQ2: Projected Growth Overview
B3: 1980 | C3: 1990 | D3: 2000 | E3: 2010 | F3: 2020 | G3: 2021 | H3: 2025 | M3: 2030 | R3: 2035 | W3: 2040 | AB3: 2045 | AG3: 2050 | AM3: 1980 - 2021 | AQ3: 2021 - 2050
A4: COUNTY | B4: Estimate (1) | C4: Estimate | D4: Estimate | E4: Estimate | F4: Estimate | G4: Estimate | H4: Forecast (2) | I4: Confidence Limit (upper) (3) | J4: Confidence Limit (lower) (3) | K4: Confidence Interval (upper) (4) | L4: Confidence Interval (lower) (4) | M4: Forecast | N4: Confidence Limit (upper) | O4: Confidence Limit (lower) | P4: Confidence Interval (upper) | Q4: Confidence Interval (lower) | R4: Forecast | S4: Confidence Limit (upper) | T4: Confidence Limit (lower) | U4: Confidence Interval (upper) | V4: Confidence Interval (lower) | W4: Forecast | X4: Confidence Limit (upper) | Y4: Confidence Limit (lower) | Z4: Confidence Interval (upper) | AA4: Confidence Interval (lower) | AB4: Forecast | AC4: Confidence Limit (upper) | AD4: Confidence Limit (lower) | AE4: Confidence Interval (upper) | AF4: Confidence Interval (lower) | AG4: Forecast | AH4: Confidence Limit (upper) | AI4: Confidence Limit (lower) | AJ4: Confidence Interval (upper) | AK4: Confidence Interval (lower) | AM4: Growth | AN4: % Growth | AO4: CAGR (5) | AQ4: Growth | AR4: % Growth | AS4: CAGR
A5: Delaware | B5: 53840 | C5: 67482 | D5: 111759 | E5: 175099 | F5: 215062 | G5: 220740 | H5: 247016 | I5: 248441 | J5: 238464 | K5: =I5-$H$5 -> 1425 | L5: =J5-$H5 -> -8552 | M5: 277484 | N5: 287218 | O5: 256467 | P5: =N5-$M5 -> 9734 | Q5: =O5-$M5 -> -21017 | R5: 310863 | S5: 329249 | T5: 271216 | U5: =S5-$R5 -> 18386 | V5: =T5-$R5 -> -39647 | W5: 340917 | X5: 373888 | Y5: 283357 | Z5: =X5-$W5 -> 32971 | AA5: =Y5-$W5 -> -57560 | AB5: 369307 | AC5: 420768 | AD5: 293257 | AE5: =AC5-$AB5 -> 51461 | AF5: =AD5-$AB5 -> -76050 | AG5: 397697 | AH5: 469644 | AI5: 301161 | AJ5: =AH5-$AG5 -> 71947 | AK5: =AI5-$AG5 -> -96536 | AM5: =G5-B5 -> 166900 | AN5: =AM5/B5 -> 3.0999257 | AO5: =(G5/B5)^(1/($G$3-$B$3))-1 -> 0.035012883 | AQ5: =AG5-G5 -> 176957 | AR5: =AQ5/G5 -> 0.80165353 | AS5: =(AG5/G5)^(1/($AG$3-$G$3))-1 -> 0.020507618
A6: Fairfield | B6: 93678 | C6: 103823 | D6: 123485 | E6: 146417 | F6: 159357 | G6: 161064 | H6: 169183 | I6: 171704 | J6: 163990 | K6: =I6-H6 -> 2521 | L6: =J6-$H6 -> -5193 | M6: 178449 | N6: 188541 | O6: 164104 | P6: =N6-$M6 -> 10092 | Q6: =O6-$M6 -> -14345 | R6: 188820 | S6: 208055 | T6: 161542 | U6: =S6-$R6 -> 19235 | V6: =T6-$R6 -> -27278 | W6: 197928 | X6: 229705 | Y6: 156843 | Z6: =X6-$W6 -> 31777 | AA6: =Y6-$W6 -> -41085 | AB6: 206404 | AC6: 253189 | AD6: 150311 | AE6: =AC6-$AB6 -> 46785 | AF6: =AD6-$AB6 -> -56093 | AG6: 214880 | AH6: 278304 | AI6: 142147 | AJ6: =AH6-$AG6 -> 63424 | AK6: =AI6-$AG6 -> -72733 | AM6: =G6-B6 -> 67386 | AN6: =AM6/B6 -> 0.71933645 | AO6: =(G6/B6)^(1/($G$3-$B$3))-1 -> 0.013305755 | AQ6: =AG6-G6 -> 53816 | AR6: =AQ6/G6 -> 0.33412805 | AS6: =(AG6/G6)^(1/($AG$3-$G$3))-1 -> 0.0099901904
A7: Fayette | B7: 27467 | C7: 27501 | D7: 28495 | E7: 29014 | F7: 28939 | G7: 28906 | H7: 29419 | I7: 29855 | J7: 28912 | K7: =I7-H7 -> 436 | L7: =J7-$H7 -> -507 | M7: 30011 | N7: 31216 | O7: 28691 | P7: =N7-$M7 -> 1205 | Q7: =O7-$M7 -> -1320 | R7: 30634 | S7: 32814 | T7: 28240 | U7: =S7-$R7 -> 2180 | V7: =T7-$R7 -> -2394 | W7: 31220 | X7: 34594 | Y7: 27601 | Z7: =X7-$W7 -> 3374 | AA7: =Y7-$W7 -> -3619 | AB7: 31790 | AC7: 36534 | AD7: 26802 | AE7: =AC7-$AB7 -> 4744 | AF7: =AD7-$AB7 -> -4988 | AG7: 32360 | AH7: 38618 | AI7: 25859 | AJ7: =AH7-$AG7 -> 6258 | AK7: =AI7-$AG7 -> -6501 | AM7: =G7-B7 -> 1439 | AN7: =AM7/B7 -> 0.052390141 | AO7: =(G7/B7)^(1/($G$3-$B$3))-1 -> 0.0012462369 | AQ7: =AG7-G7 -> 3454 | AR7: =AQ7/G7 -> 0.11949076 | AS7: =(AG7/G7)^(1/($AG$3-$G$3))-1 -> 0.0038997881
A8: Franklin | B8: 869126 | C8: 965600 | D8: 1072018 | E8: 1166202 | F8: 1324013 | G8: 1321414 | H8: 1390127 | I8: 1409654 | J8: 1333445 | K8: =I8-H8 -> 19527 | L8: =J8-$H8 -> -56682 | M8: 1447090 | N8: 1506988 | O8: 1327469 | P8: =N8-$M8 -> 59898 | Q8: =O8-$M8 -> -119621 | R8: 1519844 | S8: 1617180 | T8: 1308636 | U8: =S8-$R8 -> 97336 | V8: =T8-$R8 -> -211208 | W8: 1574551 | X8: 1738045 | Y8: 1279131 | Z8: =X8-$W8 -> 163494 | AA8: =Y8-$W8 -> -295420 | AB8: 1620232 | AC8: 1868239 | AD8: 1240296 | AE8: =AC8-$AB8 -> 248007 | AF8: =AD8-$AB8 -> -379936 | AG8: 1665914 | AH8: 2006828 | AI8: 1193066 | AJ8: =AH8-$AG8 -> 340914 | AK8: =AI8-$AG8 -> -472848 | AM8: =G8-B8 -> 452288 | AN8: =AM8/B8 -> 0.52039405 | AO8: =(G8/B8)^(1/($G$3-$B$3))-1 -> 0.010271159 | AQ8: =AG8-G8 -> 344500 | AR8: =AQ8/G8 -> 0.26070558 | AS8: =(AG8/G8)^(1/($AG$3-$G$3))-1 -> 0.0080206686
A9: Hocking | B9: 24304 | C9: 25594 | D9: 28262 | E9: 29478 | F9: 27999 | G9: 28097 | H9: 27965 | I9: 28660 | J9: 27122 | K9: =I9-H9 -> 695 | L9: =J9-$H9 -> -843 | M9: 27762 | N9: 29751 | O9: 25535 | P9: =N9-$M9 -> 1989 | Q9: =O9-$M9 -> -2227 | R9: 27629 | S9: 31239 | T9: 23571 | U9: =S9-$R9 -> 3610 | V9: =T9-$R9 -> -4058 | W9: 27428 | X9: 33041 | Y9: 21295 | Z9: =X9-$W9 -> 5613 | AA9: =Y9-$W9 -> -6133 | AB9: 27190 | AC9: 35114 | AD9: 18747 | AE9: =AC9-$AB9 -> 7924 | AF9: =AD9-$AB9 -> -8443 | AG9: 26953 | AH9: 37429 | AI9: 15958 | AJ9: =AH9-$AG9 -> 10476 | AK9: =AI9-$AG9 -> -10995 | AM9: =G9-B9 -> 3793 | AN9: =AM9/B9 -> 0.15606485 | AO9: =(G9/B9)^(1/($G$3-$B$3))-1 -> 0.0035433816 | AQ9: =AG9-G9 -> -1144 | AR9: =AQ9/G9 -> -0.040716091 | AS9: =(AG9/G9)^(1/($AG$3-$G$3))-1 -> -0.0014323594
A10: Knox | B10: 46304 | C10: 47637 | D10: 54616 | E10: 61090 | F10: 62765 | G10: 62897 | H10: 64157 | I10: 65164 | J10: 61970 | K10: =I10-H10 -> 1007 | L10: =J10-$H10 -> -2187 | M10: 65339 | N10: 69227 | O10: 59572 | P10: =N10-$M10 -> 3888 | Q10: =O10-$M10 -> -5767 | R10: 67013 | S10: 74288 | T10: 56176 | U10: =S10-$R10 -> 7275 | V10: =T10-$R10 -> -10837 | W10: 68125 | X10: 80150 | Y10: 51978 | Z10: =X10-$W10 -> 12025 | AA10: =Y10-$W10 -> -16147 | AB10: 68957 | AC10: 86702 | AD10: 47091 | AE10: =AC10-$AB10 -> 17745 | AF10: =AD10-$AB10 -> -21866 | AG10: 69790 | AH10: 93868 | AI10: 41589 | AJ10: =AH10-$AG10 -> 24078 | AK10: =AI10-$AG10 -> -28201 | AM10: =G10-B10 -> 16593 | AN10: =AM10/B10 -> 0.35834917 | AO10: =(G10/B10)^(1/($G$3-$B$3))-1 -> 0.0074979729 | AQ10: =AG10-G10 -> 6893 | AR10: =AQ10/G10 -> 0.10959187 | AS10: =(AG10/G10)^(1/($AG$3-$G$3))-1 -> 0.0035923774
A11: Licking | B11: 120981 | C11: 129006 | D11: 146268 | E11: 166705 | F11: 178680 | G11: 180401 | H11: 190915 | I11: 189312 | J11: 176808 | K11: =I11-H11 -> -1603 | L11: =J11-$H11 -> -14107 | M11: 200710 | N11: 203164 | O11: 173324 | P11: =N11-$M11 -> 2454 | Q11: =O11-$M11 -> -27386 | R11: 216962 | S11: 219200 | T11: 167658 | U11: =S11-$R11 -> 2238 | V11: =T11-$R11 -> -49304 | W11: 225833 | X11: 237045 | Y11: 160181 | Z11: =X11-$W11 -> 11212 | AA11: =Y11-$W11 -> -65652 | AB11: 231017 | AC11: 256471 | AD11: 151123 | AE11: =AC11-$AB11 -> 25454 | AF11: =AD11-$AB11 -> -79894 | AG11: 236202 | AH11: 277319 | AI11: 140644 | AJ11: =AH11-$AG11 -> 41117 | AK11: =AI11-$AG11 -> -95558 | AM11: =G11-B11 -> 59420 | AN11: =AM11/B11 -> 0.4911515 | AO11: =(G11/B11)^(1/($G$3-$B$3))-1 -> 0.0097927268 | AQ11: =AG11-G11 -> 55801 | AR11: =AQ11/G11 -> 0.30931647 | AS11: =(AG11/G11)^(1/($AG$3-$G$3))-1 -> 0.0093366001
A12: Logan | B12: 39155 | C12: 42417 | D12: 45984 | E12: 45743 | F12: 46065 | G12: 46035 | H12: 46095 | I12: 47290 | J12: 44871 | K12: =I12-H12 -> 1195 | L12: =J12-$H12 -> -1224 | M12: 46407 | N12: 49351 | O12: 43377 | P12: =N12-$M12 -> 2944 | Q12: =O12-$M12 -> -3030 | R12: 46763 | S12: 51833 | T12: 41448 | U12: =S12-$R12 -> 5070 | V12: =T12-$R12 -> -5315 | W12: 47058 | X12: 54679 | Y12: 39156 | Z12: =X12-$W12 -> 7621 | AA12: =Y12-$W12 -> -7902 | AB12: 47335 | AC12: 57844 | AD12: 36544 | AE12: =AC12-$AB12 -> 10509 | AF12: =AD12-$AB12 -> -10791 | AG12: 47611 | AH12: 61297 | AI12: 33644 | AJ12: =AH12-$AG12 -> 13686 | AK12: =AI12-$AG12 -> -13967 | AM12: =G12-B12 -> 6880 | AN12: =AM12/B12 -> 0.17571191 | AO12: =(G12/B12)^(1/($G$3-$B$3))-1 -> 0.0039559468 | AQ12: =AG12-G12 -> 1576 | AR12: =AQ12/G12 -> 0.034234821 | AS12: =(AG12/G12)^(1/($AG$3-$G$3))-1 -> 0.0011614274
A13: Madison | B13: 33004 | C13: 37111 | D13: 40218 | E13: 43434 | F13: 43823 | G13: 44386 | H13: 46487 | I13: 49508 | J13: 42918 | K13: =I13-H13 -> 3021 | L13: =J13-$H13 -> -3569 | M13: 48833 | N13: 58168 | O13: 38616 | P13: =N13-$M13 -> 9335 | Q13: =O13-$M13 -> -10217 | R13: 51412 | S13: 68798 | T13: 32345 | U13: =S13-$R13 -> 17386 | V13: =T13-$R13 -> -19067 | W13: 53726 | X13: 81014 | Y13: 24486 | Z13: =X13-$W13 -> 27288 | AA13: =Y13-$W13 -> -29240 | AB13: 55905 | AC13: 94597 | AD13: 15261 | AE13: =AC13-$AB13 -> 38692 | AF13: =AD13-$AB13 -> -40644 | AG13: 58084 | AH13: 109400 | AI13: 4816 | AJ13: =AH13-$AG13 -> 51316 | AK13: =AI13-$AG13 -> -53268 | AM13: =G13-B13 -> 11382 | AN13: =AM13/B13 -> 0.34486729 | AO13: =(G13/B13)^(1/($G$3-$B$3))-1 -> 0.0072528913 | AQ13: =AG13-G13 -> 13698 | AR13: =AQ13/G13 -> 0.30861082 | AS13: =(AG13/G13)^(1/($AG$3-$G$3))-1 -> 0.0093178375
A14: Marion | B14: 67974 | C14: 64289 | D14: 66135 | E14: 66458 | F14: 65363 | G14: 65291 | H14: 65314 | I14: 66329 | J14: 63731 | K14: =I14-H14 -> 1015 | L14: =J14-$H14 -> -1583 | M14: 65160 | N14: 66651 | O14: 62754 | P14: =N14-$M14 -> 1491 | Q14: =O14-$M14 -> -2406 | R14: 65246 | S14: 66806 | T14: 61945 | U14: =S14-$R14 -> 1560 | V14: =T14-$R14 -> -3301 | W14: 65059 | X14: 66879 | Y14: 61217 | Z14: =X14-$W14 -> 1820 | AA14: =Y14-$W14 -> -3842 | AB14: 64732 | AC14: 66903 | AD14: 60539 | AE14: =AC14-$AB14 -> 2171 | AF14: =AD14-$AB14 -> -4193 | AG14: 64405 | AH14: 66892 | AI14: 59896 | AJ14: =AH14-$AG14 -> 2487 | AK14: =AI14-$AG14 -> -4509 | AM14: =G14-B14 -> -2683 | AN14: =AM14/B14 -> -0.039470974 | AO14: =(G14/B14)^(1/($G$3-$B$3))-1 -> -0.00098173919 | AQ14: =AG14-G14 -> -886 | AR14: =AQ14/G14 -> -0.013570017 | AS14: =(AG14/G14)^(1/($AG$3-$G$3))-1 -> -0.0004710246
A15: Morrow | B15: 26480 | C15: 27784 | D15: 31813 | E15: 34790 | F15: 34964 | G15: 35151 | H15: 36425 | I15: 37323 | J15: 34476 | K15: =I15-H15 -> 898 | L15: =J15-$H15 -> -1949 | M15: 37666 | N15: 41222 | O15: 32447 | P15: =N15-$M15 -> 3556 | Q15: =O15-$M15 -> -5219 | R15: 39338 | S15: 46050 | T15: 29489 | U15: =S15-$R15 -> 6712 | V15: =T15-$R15 -> -9849 | W15: 40519 | X15: 51621 | Y15: 25788 | Z15: =X15-$W15 -> 11102 | AA15: =Y15-$W15 -> -14731 | AB15: 41454 | AC15: 57832 | AD15: 21447 | AE15: =AC15-$AB15 -> 16378 | AF15: =AD15-$AB15 -> -20007 | AG15: 42389 | AH15: 64613 | AI15: 16536 | AJ15: =AH15-$AG15 -> 22224 | AK15: =AI15-$AG15 -> -25853 | AM15: =G15-B15 -> 8671 | AN15: =AM15/B15 -> 0.32745468 | AO15: =(G15/B15)^(1/($G$3-$B$3))-1 -> 0.0069327831 | AQ15: =AG15-G15 -> 7238 | AR15: =AQ15/G15 -> 0.20591164 | AS15: =(AG15/G15)^(1/($AG$3-$G$3))-1 -> 0.0064772954
A16: Perry | B16: 31032 | C16: 31596 | D16: 34099 | E16: 36037 | F16: 35439 | G16: 35460 | H16: 36859 | I16: 38560 | J16: 34761 | K16: =I16-H16 -> 1701 | L16: =J16-$H16 -> -2098 | M16: 37415 | N16: 41469 | O16: 32732 | P16: =N16-$M16 -> 4054 | Q16: =O16-$M16 -> -4683 | R16: 38131 | S16: 44979 | T16: 30102 | U16: =S16-$R16 -> 6848 | V16: =T16-$R16 -> -8029 | W16: 38662 | X16: 48989 | Y16: 26972 | Z16: =X16-$W16 -> 10327 | AA16: =Y16-$W16 -> -11690 | AB16: 39102 | AC16: 53437 | AD16: 23404 | AE16: =AC16-$AB16 -> 14335 | AF16: =AD16-$AB16 -> -15698 | AG16: 39542 | AH16: 58278 | AI16: 19442 | AJ16: =AH16-$AG16 -> 18736 | AK16: =AI16-$AG16 -> -20100 | AM16: =G16-B16 -> 4428 | AN16: =AM16/B16 -> 0.14269142 | AO16: =(G16/B16)^(1/($G$3-$B$3))-1 -> 0.0032586239 | AQ16: =AG16-G16 -> 4082 | AR16: =AQ16/G16 -> 0.11511562 | AS16: =(AG16/G16)^(1/($AG$3-$G$3))-1 -> 0.0037642428
A17: Pickaway | B17: 43662 | C17: 48257 | D17: 52808 | E17: 55740 | F17: 58628 | G17: 59333 | H17: 62355 | I17: 66029 | J17: 58005 | K17: =I17-H17 -> 3674 | L17: =J17-$H17 -> -4350 | M17: 65891 | N17: 77450 | O17: 53249 | P17: =N17-$M17 -> 11559 | Q17: =O17-$M17 -> -12642 | R17: 69716 | S17: 91360 | T17: 46004 | U17: =S17-$R17 -> 21644 | V17: =T17-$R17 -> -23712 | W17: 73212 | X17: 107272 | Y17: 36758 | Z17: =X17-$W17 -> 34060 | AA17: =Y17-$W17 -> -36454 | AB17: 76545 | AC17: 124906 | AD17: 25789 | AE17: =AC17-$AB17 -> 48361 | AF17: =AD17-$AB17 -> -50756 | AG17: 79877 | AH17: 144076 | AI17: 13285 | AJ17: =AH17-$AG17 -> 64199 | AK17: =AI17-$AG17 -> -66592 | AM17: =G17-B17 -> 15671 | AN17: =AM17/B17 -> 0.35891622 | AO17: =(G17/B17)^(1/($G$3-$B$3))-1 -> 0.007508229 | AQ17: =AG17-G17 -> 20544 | AR17: =AQ17/G17 -> 0.34624914 | AS17: =(AG17/G17)^(1/($AG$3-$G$3))-1 -> 0.01030523
... A19: Union | B19: 29536 | C19: 32010 | D19: 41338 | E19: 52464 | F19: 63077 | G19: 64971 | H19: 66408 | I19: 69664 | J19: 62368 | K19: =I19-H19 -> 3256 | L19: =J19-$H19 -> -4040 | M19: 72505 | N19: 80350 | O19: 63404 | P19: =N19-$M19 -> 7845 | Q19: =O19-$M19 -> -9101 | R19: 78933 | S19: 92220 | T19: 63255 | U19: =S19-$R19 -> 13287 | V19: =T19-$R19 -> -15678 | W19: 84983 | X19: 105075 | Y19: 62122 | Z19: =X19-$W19 -> 20092 | AA19: =Y19-$W19 -> -22861 | AB19: 90844 | AC19: 118792 | AD19: 60127 | AE19: =AC19-$AB19 -> 27948 | AF19: =AD19-$AB19 -> -30717 | AG19: 96705 | AH19: 133284 | AI19: 57356 | AJ19: =AH19-$AG19 -> 36579 | AK19: =AI19-$AG19 -> -39349 | AM19: =G19-B19 -> 35435 | AN19: =AM19/B19 -> 1.1997224 | AO19: =(G19/B19)^(1/($G$3-$B$3))-1 -> 0.01941363 | AQ19: =AG19-G19 -> 31734 | AR19: =AQ19/G19 -> 0.4884333 | AS19: =(AG19/G19)^(1/($AG$3-$G$3))-1 -> 0.013809101
A20: Total | B20: =SUM(B5:B19) -> 1571547 | C20: =SUM(C5:C19) -> 1719508 | D20: =SUM(D5:D19) -> 1950805 | E20: =SUM(E5:E19) -> 2186769 | F20: =SUM(F5:F19) -> 2421159 | G20: =SUM(G5:G19) -> 2431037 | H20: =SUM(H5:H19) -> 2555315 | I20: =SUM(I5:I19) -> 2597188 | J20: =SUM(J5:J19) -> 2445231 | K20: =I20-H20 -> 41873 | L20: =J20-$H20 -> -110084 | M20: =SUM(M5:M19) -> 2676926 | N20: =SUM(N5:N19) -> 2816613 | O20: =SUM(O5:O19) -> 2428110 | P20: =N20-$M20 -> 139687 | Q20: =O20-$M20 -> -248816 | R20: =SUM(R5:R19) -> 2827180 | S20: =SUM(S5:S19) -> 3068141 | T20: =SUM(T5:T19) -> 2378893 | U20: =S20-$R20 -> 240961 | V20: =T20-$R20 -> -448287 | W20: =SUM(W5:W19) -> 2944699 | X20: =SUM(X5:X19) -> 3345949 | Y20: =SUM(Y5:Y19) -> 2303397 | Z20: =X20-$W20 -> 401250 | AA20: =Y20-$W20 -> -641302 | AB20: =SUM(AB5:AB19) -> 3045854 | AC20: =SUM(AC5:AC19) -> 3646586 | AD20: =SUM(AD5:AD19) -> 2205068 | AE20: =AC20-$AB20 -> 600732 | AF20: =AD20-$AB20 -> -840786 | AG20: =SUM(AG5:AG19) -> 3147011 | AH20: =SUM(AH5:AH19) -> 3967683 | AI20: =SUM(AI5:AI19) -> 2086279 | AJ20: =AH20-$AG20 -> 820672 | AK20: =AI20-$AG20 -> -1060732 | AM20: =G20-B20 -> 859490 | AN20: =AM20/B20 -> 0.54690696 | AO20: =(G20/B20)^(1/($G$3-$B$3))-1 -> 0.010697236 | AQ20: =AG20-G20 -> 715974 | AR20: =AQ20/G20 -> 0.29451382 | AS20: =(AG20/G20)^(1/($AG$3-$G$3))-1 -> 0.0089409473
A22: 1 | B22: Historic population estimates are sourced from the Census Population Estimates Program (TBD on "References" sheet)
A23: 2 | B23: Forecasts are derived from historic patterns and major expected economic developments. For more details, see the methods document (TBD on "References" sheet).
A24: 3 | B24: The confidence limits represent the highest and lowest expected population based exclusively on historic patterns. Unprecedented circumstances may cause the forecasted population to exceed these limits. For more details, see the methods document (TBD on "References" sheet).
A25: 4 | B25: The confidence intervals represent the difference between the forecast and the upper confidence limit and the forecast and the lower confidence limit.
A26: 5 | B26: CAGR, or Compound Annual Growth Rate, calculated as (value at end of period / value at beginning of period) ^ (1/ number of years in period) - 1
B28: Updated January 9, 2023

Sheet Households and Housing Units
C1: County Growth Projections Households and Housing Units
A2: Households
B3: Estimate | C3: Projections | L3: Average Household Size (1)
A4: COUNTY | B4: 2020 | C4: 2025 | D4: 2030 | E4: 2035 | F4: 2040 | G4: 2045 | H4: 2050 | L4: 2020 | M4: 2025 | N4: 2030 | O4: 2035 | P4: 2040 | Q4: 2045 | R4: 2050
A5: Delaware | B5: 74757.394 | C5: 85864.789 | D5: 96455.986 | E5: 108058.8 | F5: 118505.63 | G5: 128374.3 | H5: 138242.96 | L5: =#REF!/'Households and Housing Units'!B5 -> #REF! | M5: =#REF!/'Households and Housing Units'!C5 -> #REF! | N5: =#REF!/'Households and Housing Units'!D5 -> #REF! | O5: =#REF!/'Households and Housing Units'!E5 -> #REF! | P5: =#REF!/'Households and Housing Units'!F5 -> #REF! | Q5: =#REF!/'Households and Housing Units'!G5 -> #REF! | R5: =#REF!/'Households and Housing Units'!H5 -> #REF!
A6: Fairfield | B6: 58303.358 | C6: 61898.507 | D6: 65288.806 | E6: 69083.209 | F6: 72415.299 | G6: 75516.418 | H6: 78617.537 | L6: =#REF!/'Households and Housing Units'!B6 -> #REF! | M6: =#REF!/'Households and Housing Units'!C6 -> #REF! | N6: =#REF!/'Households and Housing Units'!D6 -> #REF! | O6: =#REF!/'Households and Housing Units'!E6 -> #REF! | P6: =#REF!/'Households and Housing Units'!F6 -> #REF! | Q6: =#REF!/'Households and Housing Units'!G6 -> #REF! | R6: =#REF!/'Households and Housing Units'!H6 -> #REF!
A7: Fayette | B7: 11875.104 | C7: 12071.784 | D7: 12314.938 | E7: 12570.539 | F7: 12811.203 | G7: 13044.813 | H7: 13278.838 | L7: =#REF!/'Households and Housing Units'!B7 -> #REF! | M7: =#REF!/'Households and Housing Units'!C7 -> #REF! | N7: =#REF!/'Households and Housing Units'!D7 -> #REF! | O7: =#REF!/'Households and Housing Units'!E7 -> #REF! | P7: =#REF!/'Households and Housing Units'!F7 -> #REF! | Q7: =#REF!/'Households and Housing Units'!G7 -> #REF! | R7: =#REF!/'Households and Housing Units'!H7 -> #REF!
A8: Franklin | B8: 526242.28 | C8: 552519.92 | D8: 575160.57 | E8: 604077.24 | F8: 625821.14 | G8: 643977.64 | H8: 662134.15 | L8: =#REF!/'Households and Housing Units'!B8 -> #REF! | M8: =#REF!/'Households and Housing Units'!C8 -> #REF! | N8: =#REF!/'Households and Housing Units'!D8 -> #REF! | O8: =#REF!/'Households and Housing Units'!E8 -> #REF! | P8: =#REF!/'Households and Housing Units'!F8 -> #REF! | Q8: =#REF!/'Households and Housing Units'!G8 -> #REF! | R8: =#REF!/'Households and Housing Units'!H8 -> #REF!
A9: Hocking | B9: 11423.237 | C9: 11409.544 | D9: 11326.556 | E9: 11272.199 | F9: 11190.456 | G9: 11093.361 | H9: 10996.68 | L9: =#REF!/'Households and Housing Units'!B9 -> #REF! | M9: =#REF!/'Households and Housing Units'!C9 -> #REF! | N9: =#REF!/'Households and Housing Units'!D9 -> #REF! | O9: =#REF!/'Households and Housing Units'!E9 -> #REF! | P9: =#REF!/'Households and Housing Units'!F9 -> #REF! | Q9: =#REF!/'Households and Housing Units'!G9 -> #REF! | R9: =#REF!/'Households and Housing Units'!H9 -> #REF!
A10: Knox | B10: 23410.317 | C10: 23929.365 | D10: 24370.238 | E10: 24994.841 | F10: 25409.524 | G10: 25719.841 | H10: 26030.556 | L10: =#REF!/'Households and Housing Units'!B10 -> #REF! | M10: =#REF!/'Households and Housing Units'!C10 -> #REF! | N10: =#REF!/'Households and Housing Units'!D10 -> #REF! | O10: =#REF!/'Households and Housing Units'!E10 -> #REF! | P10: =#REF!/'Households and Housing Units'!F10 -> #REF! | Q10: =#REF!/'Households and Housing Units'!G10 -> #REF! | R10: =#REF!/'Households and Housing Units'!H10 -> #REF!
A11: Licking | B11: 65657.519 | C11: 70153.383 | D11: 73752.632 | E11: 79724.436 | F11: 82984.211 | G11: 84889.098 | H11: 86794.361 | L11: =#REF!/'Households and Housing Units'!B11 -> #REF! | M11: =#REF!/'Households and Housing Units'!C11 -> #REF! | N11: =#REF!/'Households and Housing Units'!D11 -> #REF! | O11: =#REF!/'Households and Housing Units'!E11 -> #REF! | P11: =#REF!/'Households and Housing Units'!F11 -> #REF! | Q11: =#REF!/'Households and Housing Units'!G11 -> #REF! | R11: =#REF!/'Households and Housing Units'!H11 -> #REF!
A12: Logan | B12: 18911.203 | C12: 18923.651 | D12: 19051.452 | E12: 19197.925 | F12: 19318.672 | G12: 19432.365 | H12: 19546.058 | L12: =#REF!/'Households and Housing Units'!B12 -> #REF! | M12: =#REF!/'Households and Housing Units'!C12 -> #REF! | N12: =#REF!/'Households and Housing Units'!D12 -> #REF! | O12: =#REF!/'Households and Housing Units'!E12 -> #REF! | P12: =#REF!/'Households and Housing Units'!F12 -> #REF! | Q12: =#REF!/'Households and Housing Units'!G12 -> #REF! | R12: =#REF!/'Households and Housing Units'!H12 -> #REF!
A13: Madison | B13: 14843.846 | C13: 15746.154 | D13: 16540.769 | E13: 17414.231 | F13: 18198.077 | G13: 18936.154 | H13: 19674.231 | L13: =#REF!/'Households and Housing Units'!B13 -> #REF! | M13: =#REF!/'Households and Housing Units'!C13 -> #REF! | N13: =#REF!/'Households and Housing Units'!D13 -> #REF! | O13: =#REF!/'Households and Housing Units'!E13 -> #REF! | P13: =#REF!/'Households and Housing Units'!F13 -> #REF! | Q13: =#REF!/'Households and Housing Units'!G13 -> #REF! | R13: =#REF!/'Households and Housing Units'!H13 -> #REF!
A14: Marion | B14: 24667.355 | C14: 24649.174 | D14: 24590.909 | E14: 24623.14 | F14: 24552.893 | G14: 24429.339 | H14: 24305.785 | L14: =#REF!/'Households and Housing Units'!B14 -> #REF! | M14: =#REF!/'Households and Housing Units'!C14 -> #REF! | N14: =#REF!/'Households and Housing Units'!D14 -> #REF! | O14: =#REF!/'Households and Housing Units'!E14 -> #REF! | P14: =#REF!/'Households and Housing Units'!F14 -> #REF! | Q14: =#REF!/'Households and Housing Units'!G14 -> #REF! | R14: =#REF!/'Households and Housing Units'!H14 -> #REF!
A15: Morrow | B15: 12992.135 | C15: 13535.206 | D15: 13996.255 | E15: 14617.603 | F15: 15056.18 | G15: 15403.745 | H15: 15751.311 | L15: =#REF!/'Households and Housing Units'!B15 -> #REF! | M15: =#REF!/'Households and Housing Units'!C15 -> #REF! | N15: =#REF!/'Households and Housing Units'!D15 -> #REF! | O15: =#REF!/'Households and Housing Units'!E15 -> #REF! | P15: =#REF!/'Households and Housing Units'!F15 -> #REF! | Q15: =#REF!/'Households and Housing Units'!G15 -> #REF! | R15: =#REF!/'Households and Housing Units'!H15 -> #REF!
A16: Perry | B16: 13000 | C16: 13521.111 | D16: 13724.815 | E16: 13987.407 | F16: 14182.222 | G16: 14343.704 | H16: 14505.185 | L16: =#REF!/'Households and Housing Units'!B16 -> #REF! | M16: =#REF!/'Households and Housing Units'!C16 -> #REF! | N16: =#REF!/'Households and Housing Units'!D16 -> #REF! | O16: =#REF!/'Households and Housing Units'!E16 -> #REF! | P16: =#REF!/'Households and Housing Units'!F16 -> #REF! | Q16: =#REF!/'Households and Housing Units'!G16 -> #REF! | R16: =#REF!/'Households and Housing Units'!H16 -> #REF!
... A19: Union | B19: 22547.348 | C19: 23737.879 | D19: 25917.424 | E19: 28215.152 | F19: 30377.652 | G19: 32472.727 | H19: 34567.803 | L19: =#REF!/'Households and Housing Units'!B19 -> #REF! | M19: =#REF!/'Households and Housing Units'!C19 -> #REF! | N19: =#REF!/'Households and Housing Units'!D19 -> #REF! | O19: =#REF!/'Households and Housing Units'!E19 -> #REF! | P19: =#REF!/'Households and Housing Units'!F19 -> #REF! | Q19: =#REF!/'Households and Housing Units'!G19 -> #REF! | R19: =#REF!/'Households and Housing Units'!H19 -> #REF!
A20: Total | B20: =SUM(B5:B19) -> 927777.8 | C20: =SUM(C5:C19) -> 978229.06 | D20: =SUM(D5:D19) -> 1023819.6 | E20: =SUM(E5:E19) -> 1080345.2 | F20: =SUM(F5:F19) -> 1124373.8 | G20: =SUM(G5:G19) -> 1162154.8 | H20: =SUM(H5:H19) -> 1199937.5 | L20: =#REF!/'Households and Housing Units'!B20 -> #REF! | M20: =#REF!/'Households and Housing Units'!C20 -> #REF! | N20: =#REF!/'Households and Housing Units'!D20 -> #REF! | O20: =#REF!/'Households and Housing Units'!E20 -> #REF! | P20: =#REF!/'Households and Housing Units'!F20 -> #REF! | Q20: =#REF!/'Households and Housing Units'!G20 -> #REF! | R20: =#REF!/'Households and Housing Units'!H20 -> #REF!
A22: Housing Units
B23: Estimate | C23: Projections | L23: Occupancy Rate (2)
A24: COUNTY | B24: 2020 | C24: 2025 | D24: 2030 | E24: 2035 | F24: 2040 | G24: 2045 | H24: 2050 | L24: 2020 | M24: 2025 | N24: 2030 | O24: 2035 | P24: 2040 | Q24: 2045 | R24: 2050
A25: Delaware | B25: 78113.695 | C25: 89719.766 | D25: 100786.46 | E25: 112910.2 | F25: 123826.05 | G25: 134137.78 | H25: 144449.5 | L25: =B5/B25 -> 0.95703313 | M25: =C5/C25 -> 0.95703313 | N25: =D5/D25 -> 0.95703313 | O25: =E5/E25 -> 0.95703313 | P25: =F5/F25 -> 0.95703313 | Q25: =G5/G25 -> 0.95703313 | R25: =H5/H25 -> 0.95703313
A26: Fairfield | B26: 62896.442 | C26: 66774.814 | D26: 70432.197 | E26: 74525.52 | F26: 78120.108 | G26: 81465.531 | H26: 84810.953 | L26: =B6/B26 -> 0.92697387 | M26: =C6/C26 -> 0.92697387 | N26: =D6/D26 -> 0.92697387 | O26: =E6/E26 -> 0.92697387 | P26: =F6/F26 -> 0.92697387 | Q26: =G6/G26 -> 0.92697387 | R26: =H6/H26 -> 0.92697387
A27: Fayette | B27: 12959.717 | C27: 13174.362 | D27: 13439.724 | E27: 13718.671 | F27: 13981.316 | G27: 14236.263 | H27: 14491.662 | L27: =B7/B27 -> 0.91630885 | M27: =C7/C27 -> 0.91630885 | N27: =D7/D27 -> 0.91630885 | O27: =E7/E27 -> 0.91630885 | P27: =F7/F27 -> 0.91630885 | Q27: =G7/G27 -> 0.91630885 | R27: =H7/H27 -> 0.91630885
A28: Franklin | B28: 567026.19 | C28: 595340.35 | D28: 619735.66 | E28: 650893.38 | F28: 674322.44 | G28: 693886.07 | H28: 713449.71 | L28: =B8/B28 -> 0.92807403 | M28: =C8/C28 -> 0.92807403 | N28: =D8/D28 -> 0.92807403 | O28: =E8/E28 -> 0.92807403 | P28: =F8/F28 -> 0.92807403 | Q28: =G8/G28 -> 0.92807403 | R28: =H8/H28 -> 0.92807403
A29: Hocking | B29: 13309.115 | C29: 13293.162 | D29: 13196.474 | E29: 13133.143 | F29: 13037.905 | G29: 12924.78 | H29: 12812.139 | L29: =B9/B29 -> 0.8583017 | M29: =C9/C29 -> 0.8583017 | N29: =D9/D29 -> 0.8583017 | O29: =E9/E29 -> 0.8583017 | P29: =F9/F29 -> 0.8583017 | Q29: =G9/G29 -> 0.8583017 | R29: =H9/H29 -> 0.8583017
A30: Knox | B30: 26330.126 | C30: 26913.911 | D30: 27409.771 | E30: 28112.277 | F30: 28578.68 | G30: 28927.701 | H30: 29277.168 | L30: =B10/B30 -> 0.88910769 | M30: =C10/C30 -> 0.88910769 | N30: =D10/D30 -> 0.88910769 | O30: =E10/E30 -> 0.88910769 | P30: =F10/F30 -> 0.88910769 | Q30: =G10/G30 -> 0.88910769 | R30: =H10/H30 -> 0.88910769
A31: Licking | B31: 72346.915 | C31: 77300.832 | D31: 81266.783 | E31: 87847.014 | F31: 91438.904 | G31: 93537.868 | H31: 95637.245 | L31: =B11/B31 -> 0.90753724 | M31: =C11/C31 -> 0.90753724 | N31: =D11/D31 -> 0.90753724 | O31: =E11/E31 -> 0.90753724 | P31: =F11/F31 -> 0.90753724 | Q31: =G11/G31 -> 0.90753724 | R31: =H11/H31 -> 0.90753724
A32: Logan | B32: 23837.224 | C32: 23852.915 | D32: 24014.005 | E32: 24198.632 | F32: 24350.831 | G32: 24494.139 | H32: 24637.447 | L32: =B12/B32 -> 0.79334755 | M32: =C12/C32 -> 0.79334755 | N32: =D12/D32 -> 0.79334755 | O32: =E12/E32 -> 0.79334755 | P32: =F12/F32 -> 0.79334755 | Q32: =G12/G32 -> 0.79334755 | R32: =H12/H32 -> 0.79334755
A33: Madison | B33: 15956.863 | C33: 16926.827 | D33: 17781.024 | E33: 18719.979 | F33: 19562.599 | G33: 20356.019 | H33: 21149.438 | L33: =B13/B33 -> 0.9302484 | M33: =C13/C33 -> 0.9302484 | N33: =D13/D33 -> 0.9302484 | O33: =E13/E33 -> 0.9302484 | P33: =F13/F33 -> 0.9302484 | Q33: =G13/G33 -> 0.9302484 | R33: =H13/H33 -> 0.9302484
A34: Marion | B34: 27935.026 | C34: 27914.436 | D34: 27848.453 | E34: 27884.954 | F34: 27805.4 | G34: 27665.479 | H34: 27525.559 | L34: =B14/B34 -> 0.88302604 | M34: =C14/C34 -> 0.88302604 | N34: =D14/D34 -> 0.88302604 | O34: =E14/E34 -> 0.88302604 | P34: =F14/F34 -> 0.88302604 | Q34: =G14/G34 -> 0.88302604 | R34: =H14/H34 -> 0.88302604
A35: Morrow | B35: 14258.132 | C35: 14854.122 | D35: 15360.097 | E35: 16041.991 | F35: 16523.304 | G35: 16904.738 | H35: 17286.171 | L35: =B15/B35 -> 0.91120876 | M35: =C15/C35 -> 0.91120876 | N35: =D15/D35 -> 0.91120876 | O35: =E15/E35 -> 0.91120876 | P35: =F15/F35 -> 0.91120876 | Q35: =G15/G35 -> 0.91120876 | R35: =H15/H35 -> 0.91120876
A36: Perry | B36: 15109.942 | C36: 15715.632 | D36: 15952.397 | E36: 16257.609 | F36: 16484.043 | G36: 16671.734 | H36: 16859.424 | L36: =B16/B36 -> 0.86036065 | M36: =C16/C36 -> 0.86036065 | N36: =D16/D36 -> 0.86036065 | O36: =E16/E36 -> 0.86036065 | P36: =F16/F36 -> 0.86036065 | Q36: =G16/G36 -> 0.86036065 | R36: =H16/H36 -> 0.86036065
... A39: Union | B39: 23727.285 | C39: 24980.117 | D39: 27273.721 | E39: 29691.692 | F39: 31967.359 | G39: 34172.073 | H39: 36376.787 | L39: =B19/B39 -> 0.95027092 | M39: =C19/C39 -> 0.95027092 | N39: =D19/D39 -> 0.95027092 | O39: =E19/E39 -> 0.95027092 | P39: =F19/F39 -> 0.95027092 | Q39: =G19/G39 -> 0.95027092 | R39: =H19/H39 -> 0.95027092
A40: Total | B40: =SUM(B25:B39) -> 1007688 | C40: =SUM(C25:C39) -> 1061860.3 | D40: =SUM(D25:D39) -> 1110745.8 | E40: =SUM(E25:E39) -> 1171465.6 | F40: =SUM(F25:F39) -> 1218660.5 | G40: =SUM(G25:G39) -> 1259094.8 | H40: =SUM(H25:H39) -> 1299530.8 | L40: =B20/B40 -> 0.92069942 | M40: =C20/C40 -> 0.92124083 | N40: =D20/D40 -> 0.92174063 | O40: =E20/E40 -> 0.92221671 | P40: =F20/F40 -> 0.92263087 | Q40: =G20/G40 -> 0.92300825 | R40: =H20/H40 -> 0.92336209
A43: 1 | B43: Average Household Size is assumed as a fixed value, by county. See methods document for more information (TBD on "References" sheet)
A44: 2 | B44: Occupancy rate is assumed as a fixed value, by county. See methods document for more information (TBD on "References" sheet)
B46: Updated January 9, 2023

Sheet Residential Labor Force
C1: County Growth Projections Residential Labor Force
A2: Residential Labor Force
B3: Estimate | C3: Projections | L3: Share of 18 - 64 Population (1)
B4: 2020 | C4: 2025 | D4: 2030 | E4: 2035 | F4: 2040 | G4: 2045 | H4: 2050 | L4: 2020 | M4: 2025 | N4: 2030 | O4: 2035 | P4: 2040 | Q4: 2045 | R4: 2050
A5: Delaware | B5: 114891.03 | C5: 131476.76 | D5: 145904.4 | E5: 161284.48 | F5: 175629.36 | G5: 189645.64 | H5: 204383.62 | L5: =B5/#REF! -> #REF! | M5: =C5/#REF! -> #REF! | N5: =D5/#REF! -> #REF! | O5: =E5/#REF! -> #REF! | P5: =F5/#REF! -> #REF! | Q5: =G5/#REF! -> #REF! | R5: =H5/#REF! -> #REF!
A6: Fairfield | B6: 79709.989 | C6: 83296.056 | D6: 86600.857 | E6: 91260.228 | F6: 96135.047 | G6: 101091.31 | H6: 105854.28 | L6: =B6/#REF! -> #REF! | M6: =C6/#REF! -> #REF! | N6: =D6/#REF! -> #REF! | O6: =E6/#REF! -> #REF! | P6: =F6/#REF! -> #REF! | Q6: =G6/#REF! -> #REF! | R6: =H6/#REF! -> #REF!
A7: Fayette | B7: 13086.306 | C7: 13264.938 | D7: 13505.883 | E7: 13716.199 | F7: 13914.372 | G7: 14175.133 | H7: 14485.299 | L7: =B7/#REF! -> #REF! | M7: =C7/#REF! -> #REF! | N7: =D7/#REF! -> #REF! | O7: =E7/#REF! -> #REF! | P7: =F7/#REF! -> #REF! | Q7: =G7/#REF! -> #REF! | R7: =H7/#REF! -> #REF!
A8: Franklin | B8: 726058.27 | C8: 752800.92 | D8: 777956.63 | E8: 816413.73 | F8: 849684.9 | G8: 878073.12 | H8: 902582.52 | L8: =B8/#REF! -> #REF! | M8: =C8/#REF! -> #REF! | N8: =D8/#REF! -> #REF! | O8: =E8/#REF! -> #REF! | P8: =F8/#REF! -> #REF! | Q8: =G8/#REF! -> #REF! | R8: =H8/#REF! -> #REF!
A9: Hocking | B9: 13141.639 | C9: 12788.824 | D9: 12437.538 | E9: 12283.004 | F9: 12196.288 | G9: 12177.602 | H9: 12125.391 | L9: =B9/#REF! -> #REF! | M9: =C9/#REF! -> #REF! | N9: =D9/#REF! -> #REF! | O9: =E9/#REF! -> #REF! | P9: =F9/#REF! -> #REF! | Q9: =G9/#REF! -> #REF! | R9: =H9/#REF! -> #REF!
A10: Knox | B10: 30472.511 | C10: 30473.189 | D10: 30471.211 | E10: 31056.438 | F10: 31734.466 | G10: 32525.099 | H10: 33238.261 | L10: =B10/#REF! -> #REF! | M10: =C10/#REF! -> #REF! | N10: =D10/#REF! -> #REF! | O10: =E10/#REF! -> #REF! | P10: =F10/#REF! -> #REF! | Q10: =G10/#REF! -> #REF! | R10: =H10/#REF! -> #REF!
A11: Licking | B11: 89406.901 | C11: 93965.212 | D11: 97613.208 | E11: 105358.47 | F11: 110540.55 | G11: 114492.42 | H11: 117967.05 | L11: =B11/#REF! -> #REF! | M11: =C11/#REF! -> #REF! | N11: =D11/#REF! -> #REF! | O11: =E11/#REF! -> #REF! | P11: =F11/#REF! -> #REF! | Q11: =G11/#REF! -> #REF! | R11: =H11/#REF! -> #REF!
A12: Logan | B12: 22388.944 | C12: 21992.315 | D12: 21828.746 | E12: 21857.745 | F12: 22077.095 | G12: 22453.776 | H12: 22801.514 | L12: =B12/#REF! -> #REF! | M12: =C12/#REF! -> #REF! | N12: =D12/#REF! -> #REF! | O12: =E12/#REF! -> #REF! | P12: =F12/#REF! -> #REF! | Q12: =G12/#REF! -> #REF! | R12: =H12/#REF! -> #REF!
A13: Madison | B13: 19955.522 | C13: 20908.854 | D13: 21657.124 | E13: 22624.475 | F13: 23610.844 | G13: 24560.82 | H13: 25542.477 | L13: =B13/#REF! -> #REF! | M13: =C13/#REF! -> #REF! | N13: =D13/#REF! -> #REF! | O13: =E13/#REF! -> #REF! | P13: =F13/#REF! -> #REF! | Q13: =G13/#REF! -> #REF! | R13: =H13/#REF! -> #REF!
A14: Marion | B14: 27946.556 | C14: 27272.521 | D14: 27069.157 | E14: 27464.071 | F14: 27754.515 | G14: 27739.503 | H14: 27541.577 | L14: =B14/#REF! -> #REF! | M14: =C14/#REF! -> #REF! | N14: =D14/#REF! -> #REF! | O14: =E14/#REF! -> #REF! | P14: =F14/#REF! -> #REF! | Q14: =G14/#REF! -> #REF! | R14: =H14/#REF! -> #REF!
A15: Morrow | B15: 18035.828 | C15: 18578.313 | D15: 18773.04 | E15: 19295.43 | F15: 19800.099 | G15: 20351.247 | H15: 20982.376 | L15: =B15/#REF! -> #REF! | M15: =C15/#REF! -> #REF! | N15: =D15/#REF! -> #REF! | O15: =E15/#REF! -> #REF! | P15: =F15/#REF! -> #REF! | Q15: =G15/#REF! -> #REF! | R15: =H15/#REF! -> #REF!
A16: Perry | B16: 15811.99 | C16: 16033.769 | D16: 15974.353 | E16: 16105.778 | F16: 16316.898 | G16: 16579.87 | H16: 16862.283 | L16: =B16/#REF! -> #REF! | M16: =C16/#REF! -> #REF! | N16: =D16/#REF! -> #REF! | O16: =E16/#REF! -> #REF! | P16: =F16/#REF! -> #REF! | Q16: =G16/#REF! -> #REF! | R16: =H16/#REF! -> #REF!
... A19: Union | B19: 32882.176 | C19: 33740.532 | D19: 35959.183 | E19: 38741.017 | F19: 41973.974 | G19: 45509.674 | H19: 48938.99 | L19: =B19/#REF! -> #REF! | M19: =C19/#REF! -> #REF! | N19: =D19/#REF! -> #REF! | O19: =E19/#REF! -> #REF! | P19: =F19/#REF! -> #REF! | Q19: =G19/#REF! -> #REF! | R19: =H19/#REF! -> #REF!
A20: Total | B20: =SUM(B5:B19) -> 1262535.5 | C20: =SUM(C5:C19) -> 1316066.3 | D20: =SUM(D5:D19) -> 1366083.2 | E20: =SUM(E5:E19) -> 1439248 | F20: =SUM(F5:F19) -> 1504751.9 | G20: =SUM(G5:G19) -> 1564248.9 | H20: =SUM(H5:H19) -> 1619518.8 | L20: =B20/#REF! -> #REF! | M20: =C20/#REF! -> #REF! | N20: =D20/#REF! -> #REF! | O20: =E20/#REF! -> #REF! | P20: =F20/#REF! -> #REF! | Q20: =G20/#REF! -> #REF! | R20: =H20/#REF! -> #REF!
A22: Residential Employed Workers
B23: Estimate | C23: Projections | L23: Unemployment Rate
B24: 2020 | C24: 2025 | D24: 2030 | E24: 2035 | F24: 2040 | G24: 2045 | H24: 2050 | L24: 2020 | M24: 2025 | N24: 2030 | O24: 2035 | P24: 2040 | Q24: 2045 | R24: 2050
A25: Delaware | B25: 111823.5 | C25: 128006.63 | D25: 142088.17 | E25: 157109.94 | F25: 171104.14 | G25: 184757.85 | H25: 199090.56 | L25: =1-(B25/B5) -> 0.026699412 | M25: =1-(C25/C5) -> 0.026393528 | N25: =1-(D25/D5) -> 0.026155668 | O25: =1-(E25/E5) -> 0.02588306 | P25: =1-(F25/F5) -> 0.025765705 | Q25: =1-(G25/G5) -> 0.025773257 | R25: =1-(H25/H5) -> 0.02589765
A26: Fairfield | B26: 76347.247 | C26: 79760.693 | D26: 82935.604 | E26: 87410.685 | F26: 92080.633 | G26: 96820.909 | H26: 101371.46 | L26: =1-(B26/B6) -> 0.04218722 | M26: =1-(C26/C6) -> 0.042443333 | N26: =1-(D26/D6) -> 0.042323514 | O26: =1-(E26/E6) -> 0.04218204 | P26: =1-(F26/F6) -> 0.042174152 | Q26: =1-(G26/G6) -> 0.042242979 | R26: =1-(H26/H6) -> 0.042348945
A27: Fayette | B27: 12431.126 | C27: 12597.455 | D27: 12828.405 | E27: 13025.055 | F27: 13226.896 | G27: 13478.679 | H27: 13770.887 | L27: =1-(B27/B7) -> 0.050066105 | M27: =1-(C27/C7) -> 0.050319338 | N27: =1-(D27/D7) -> 0.050161686 | O27: =1-(E27/E7) -> 0.050388877 | P27: =1-(F27/F7) -> 0.049407606 | Q27: =1-(G27/G7) -> 0.049132108 | R27: =1-(H27/H7) -> 0.049319789
A28: Franklin | B28: 690360.95 | C28: 715734.89 | D28: 739552.42 | E28: 776337.46 | F28: 807962.49 | G28: 835003.08 | H28: 858361.98 | L28: =1-(B28/B8) -> 0.049165916 | M28: =1-(C28/C8) -> 0.049237492 | N28: =1-(D28/D8) -> 0.049365487 | O28: =1-(E28/E8) -> 0.04908818 | P28: =1-(F28/F8) -> 0.049103398 | Q28: =1-(G28/G8) -> 0.049050639 | R28: =1-(H28/H8) -> 0.048993343
A29: Hocking | B29: 12643.388 | C29: 12312.2 | D29: 11974.165 | E29: 11825.885 | F29: 11744.512 | G29: 11724.735 | H29: 11670.926 | L29: =1-(B29/B9) -> 0.037913933 | M29: =1-(C29/C9) -> 0.03726878 | N29: =1-(D29/D9) -> 0.037256034 | O29: =1-(E29/E9) -> 0.037215546 | P29: =1-(F29/F9) -> 0.037042143 | Q29: =1-(G29/G9) -> 0.037188501 | R29: =1-(H29/H9) -> 0.037480417
A30: Knox | B30: 29158.393 | C30: 29147.431 | D30: 29137.207 | E30: 29692.543 | F30: 30332.824 | G30: 31082.578 | H30: 31761.578 | L30: =1-(B30/B10) -> 0.043124714 | M30: =1-(C30/C10) -> 0.043505729 | N30: =1-(D30/D10) -> 0.043779157 | O30: =1-(E30/E10) -> 0.043916659 | P30: =1-(F30/F10) -> 0.044167826 | Q30: =1-(G30/G10) -> 0.044351002 | R30: =1-(H30/H10) -> 0.044427221
A31: Licking | B31: 85902.537 | C31: 90274.538 | D31: 93767.988 | E31: 101203.66 | F31: 106181.88 | G31: 109994.78 | H31: 113350.08 | L31: =1-(B31/B11) -> 0.039195675 | M31: =1-(C31/C11) -> 0.039277022 | N31: =1-(D31/D11) -> 0.039392416 | O31: =1-(E31/E11) -> 0.039434984 | P31: =1-(F31/F11) -> 0.039430457 | Q31: =1-(G31/G11) -> 0.039283345 | R31: =1-(H31/H11) -> 0.039137775
A32: Logan | B32: 21388.48 | C32: 21022.466 | D32: 20869.831 | E32: 20901.565 | F32: 21107.152 | G32: 21462.942 | H32: 21791.719 | L32: =1-(B32/B12) -> 0.044685598 | M32: =1-(C32/C12) -> 0.044099464 | N32: =1-(D32/D12) -> 0.043928976 | O32: =1-(E32/E12) -> 0.043745601 | P32: =1-(F32/F12) -> 0.043934342 | Q32: =1-(G32/G12) -> 0.044127711 | R32: =1-(H32/H12) -> 0.04428632
A33: Madison | B33: 19186.001 | C33: 20105.599 | D33: 20831.419 | E33: 21764.601 | F33: 22723.98 | G33: 23654.762 | H33: 24605.559 | L33: =1-(B33/B13) -> 0.038561812 | M33: =1-(C33/C13) -> 0.038416959 | N33: =1-(D33/D13) -> 0.03812626 | O33: =1-(E33/E13) -> 0.03800635 | P33: =1-(F33/F13) -> 0.037561754 | Q33: =1-(G33/G13) -> 0.036890396 | R33: =1-(H33/H13) -> 0.036680791
A34: Marion | B34: 26201.029 | C34: 25549.81 | D34: 25334.406 | E34: 25686.584 | F34: 25957.784 | G34: 25958.267 | H34: 25798.325 | L34: =1-(B34/B14) -> 0.06245946 | M34: =1-(C34/C14) -> 0.063166557 | N34: =1-(D34/D14) -> 0.064085901 | O34: =1-(E34/E14) -> 0.064720463 | P34: =1-(F34/F14) -> 0.064736548 | Q34: =1-(G34/G14) -> 0.064212977 | R34: =1-(H34/H14) -> 0.063295296
A35: Morrow | B35: 17535.005 | C35: 18063.127 | D35: 18272.944 | E35: 18785.608 | F35: 19265.302 | G35: 19803.766 | H35: 20422.376 | L35: =1-(B35/B15) -> 0.027768223 | M35: =1-(C35/C15) -> 0.0277305 | N35: =1-(D35/D15) -> 0.02663904 | O35: =1-(E35/E15) -> 0.026421905 | P35: =1-(F35/F15) -> 0.027009823 | Q35: =1-(G35/G15) -> 0.026901596 | R35: =1-(H35/H15) -> 0.026689066
A36: Perry | B36: 14855.114 | C36: 15057.065 | D36: 15009.652 | E36: 15144.063 | F36: 15335.683 | G36: 15578.479 | H36: 15843.427 | L36: =1-(B36/B16) -> 0.060515856 | M36: =1-(C36/C16) -> 0.060915417 | N36: =1-(D36/D16) -> 0.060390672 | O36: =1-(E36/E16) -> 0.0597124 | P36: =1-(F36/F16) -> 0.060134872 | Q36: =1-(G36/G16) -> 0.060398035 | R36: =1-(H36/H16) -> 0.060422223
... A39: Union | B39: 31920.045 | C39: 32773.431 | D39: 34938.226 | E39: 37625.143 | F39: 40733.21 | G39: 44136.471 | H39: 47472.25 | L39: =1-(B39/B19) -> 0.029259945 | M39: =1-(C39/C19) -> 0.028662904 | N39: =1-(D39/D19) -> 0.028392101 | O39: =1-(E39/E19) -> 0.02880342 | P39: =1-(F39/F19) -> 0.029560328 | Q39: =1-(G39/G19) -> 0.030173884 | R39: =1-(H39/H19) -> 0.029970776
A40: Total | B40: =SUM(B25:B39) -> 1205278.3 | C40: =SUM(C25:C39) -> 1256629.2 | D40: =SUM(D25:D39) -> 1304584.9 | E40: =SUM(E25:E39) -> 1374942 | F40: =SUM(F25:F39) -> 1437746.5 | G40: =SUM(G25:G39) -> 1494886.2 | H40: =SUM(H25:H39) -> 1548049.1 | L40: =1-(B40/B20) -> 0.045350971 | M40: =1-(C40/C20) -> 0.045162724 | N40: =1-(D40/D20) -> 0.045018035 | O40: =1-(E40/E20) -> 0.044680319 | P40: =1-(F40/F20) -> 0.044529182 | Q40: =1-(G40/G20) -> 0.044342498 | R40: =1-(H40/H20) -> 0.044130178
A43: 1 | B43: Labor force is estimated based on participation among age groups from ages 16 - 79, though the vast majority of people in the labor force are between the ages of 18 and 64. See methods document for more information (TBD on "References" sheet.)
B45: Updated January 9, 2023
